[2023-11-04T03:25:32.252+0000] {logging_mixin.py:151} INFO - Changing /opt/***/logs/dag_id=col_api_etl/run_id=manual__2023-11-04T03:16:58.704133+00:00/task_id=merge_and_transform_rent permission to 509
[2023-11-04T03:25:32.253+0000] {logging_mixin.py:151} INFO - Failed to change /opt/***/logs/dag_id=col_api_etl/run_id=manual__2023-11-04T03:16:58.704133+00:00/task_id=merge_and_transform_rent permission to 509: [Errno 1] Operation not permitted: '/opt/***/logs/dag_id=col_api_etl/run_id=manual__2023-11-04T03:16:58.704133+00:00/task_id=merge_and_transform_rent'
[2023-11-04T03:25:32.279+0000] {logging_mixin.py:151} INFO - Changing /opt/***/logs/dag_id=col_api_etl/run_id=manual__2023-11-04T03:16:58.704133+00:00/task_id=merge_and_transform_rent permission to 509
[2023-11-04T03:25:32.279+0000] {logging_mixin.py:151} INFO - Failed to change /opt/***/logs/dag_id=col_api_etl/run_id=manual__2023-11-04T03:16:58.704133+00:00/task_id=merge_and_transform_rent permission to 509: [Errno 1] Operation not permitted: '/opt/***/logs/dag_id=col_api_etl/run_id=manual__2023-11-04T03:16:58.704133+00:00/task_id=merge_and_transform_rent'
[2023-11-04T03:25:32.312+0000] {taskinstance.py:1159} INFO - Dependencies all met for dep_context=non-requeueable deps ti=<TaskInstance: col_api_etl.merge_and_transform_rent manual__2023-11-04T03:16:58.704133+00:00 [queued]>
[2023-11-04T03:25:32.321+0000] {taskinstance.py:1159} INFO - Dependencies all met for dep_context=requeueable deps ti=<TaskInstance: col_api_etl.merge_and_transform_rent manual__2023-11-04T03:16:58.704133+00:00 [queued]>
[2023-11-04T03:25:32.322+0000] {taskinstance.py:1361} INFO - Starting attempt 1 of 1
[2023-11-04T03:25:32.336+0000] {taskinstance.py:1382} INFO - Executing <Task(PythonOperator): merge_and_transform_rent> on 2023-11-04 03:16:58.704133+00:00
[2023-11-04T03:25:32.343+0000] {standard_task_runner.py:57} INFO - Started process 38342 to run task
[2023-11-04T03:25:32.343+0000] {clientserver.py:543} INFO - Closing down clientserver connection
[2023-11-04T03:25:32.347+0000] {standard_task_runner.py:84} INFO - Running: ['***', 'tasks', 'run', 'col_api_etl', 'merge_and_transform_rent', 'manual__2023-11-04T03:16:58.704133+00:00', '--job-id', '1306', '--raw', '--subdir', 'DAGS_FOLDER/col_api_etl.py', '--cfg-path', '/tmp/tmpi38o2rlh']
[2023-11-04T03:25:32.350+0000] {standard_task_runner.py:85} INFO - Job 1306: Subtask merge_and_transform_rent
[2023-11-04T03:25:32.391+0000] {logging_mixin.py:151} INFO - Changing /opt/***/logs/dag_id=col_api_etl/run_id=manual__2023-11-04T03:16:58.704133+00:00/task_id=merge_and_transform_rent permission to 509
[2023-11-04T03:25:32.392+0000] {logging_mixin.py:151} INFO - Failed to change /opt/***/logs/dag_id=col_api_etl/run_id=manual__2023-11-04T03:16:58.704133+00:00/task_id=merge_and_transform_rent permission to 509: [Errno 1] Operation not permitted: '/opt/***/logs/dag_id=col_api_etl/run_id=manual__2023-11-04T03:16:58.704133+00:00/task_id=merge_and_transform_rent'
[2023-11-04T03:25:32.394+0000] {task_command.py:415} INFO - Running <TaskInstance: col_api_etl.merge_and_transform_rent manual__2023-11-04T03:16:58.704133+00:00 [running]> on host 0bcf85c4b011
[2023-11-04T03:25:32.610+0000] {taskinstance.py:1660} INFO - Exporting env vars: AIRFLOW_CTX_DAG_OWNER='***' AIRFLOW_CTX_DAG_ID='col_api_etl' AIRFLOW_CTX_TASK_ID='merge_and_transform_rent' AIRFLOW_CTX_EXECUTION_DATE='2023-11-04T03:16:58.704133+00:00' AIRFLOW_CTX_TRY_NUMBER='1' AIRFLOW_CTX_DAG_RUN_ID='manual__2023-11-04T03:16:58.704133+00:00'
[2023-11-04T03:25:33.147+0000] {clientserver.py:505} INFO - Error while sending or receiving.
Traceback (most recent call last):
  File "/home/airflow/.local/lib/python3.8/site-packages/py4j/clientserver.py", line 503, in send_command
    self.socket.sendall(command.encode("utf-8"))
ConnectionResetError: [Errno 104] Connection reset by peer
[2023-11-04T03:25:33.148+0000] {clientserver.py:543} INFO - Closing down clientserver connection
[2023-11-04T03:25:33.149+0000] {java_gateway.py:1052} INFO - Exception while sending command.
Traceback (most recent call last):
  File "/home/airflow/.local/lib/python3.8/site-packages/py4j/clientserver.py", line 503, in send_command
    self.socket.sendall(command.encode("utf-8"))
ConnectionResetError: [Errno 104] Connection reset by peer

During handling of the above exception, another exception occurred:

Traceback (most recent call last):
  File "/home/airflow/.local/lib/python3.8/site-packages/py4j/java_gateway.py", line 1038, in send_command
    response = connection.send_command(command)
  File "/home/airflow/.local/lib/python3.8/site-packages/py4j/clientserver.py", line 506, in send_command
    raise Py4JNetworkError(
py4j.protocol.Py4JNetworkError: Error while sending
[2023-11-04T03:25:33.151+0000] {clientserver.py:543} INFO - Closing down clientserver connection
[2023-11-04T03:25:40.568+0000] {logging_mixin.py:151} INFO - +----+-------------+-----------------+--------+
|City|Monthly Price|Property Location|Bedrooms|
+----+-------------+-----------------+--------+
+----+-------------+-----------------+--------+
[2023-11-04T03:25:42.708+0000] {python.py:194} INFO - Done. Returned value was: None
[2023-11-04T03:25:42.720+0000] {taskinstance.py:1400} INFO - Marking task as SUCCESS. dag_id=col_api_etl, task_id=merge_and_transform_rent, execution_date=20231104T031658, start_date=20231104T032532, end_date=20231104T032542
[2023-11-04T03:25:42.759+0000] {local_task_job_runner.py:228} INFO - Task exited with return code 0
