[2023-11-01T23:06:04.269+0000] {logging_mixin.py:151} INFO - Changing /opt/***/logs/dag_id=col_api_etl/run_id=manual__2023-11-01T23:05:52.250695+00:00/task_id=extract_currency_conversion_rates permission to 509
[2023-11-01T23:06:04.272+0000] {logging_mixin.py:151} INFO - Failed to change /opt/***/logs/dag_id=col_api_etl/run_id=manual__2023-11-01T23:05:52.250695+00:00/task_id=extract_currency_conversion_rates permission to 509: [Errno 1] Operation not permitted: '/opt/***/logs/dag_id=col_api_etl/run_id=manual__2023-11-01T23:05:52.250695+00:00/task_id=extract_currency_conversion_rates'
[2023-11-01T23:06:04.551+0000] {logging_mixin.py:151} INFO - Changing /opt/***/logs/dag_id=col_api_etl/run_id=manual__2023-11-01T23:05:52.250695+00:00/task_id=extract_currency_conversion_rates permission to 509
[2023-11-01T23:06:04.564+0000] {logging_mixin.py:151} INFO - Failed to change /opt/***/logs/dag_id=col_api_etl/run_id=manual__2023-11-01T23:05:52.250695+00:00/task_id=extract_currency_conversion_rates permission to 509: [Errno 1] Operation not permitted: '/opt/***/logs/dag_id=col_api_etl/run_id=manual__2023-11-01T23:05:52.250695+00:00/task_id=extract_currency_conversion_rates'
[2023-11-01T23:06:04.862+0000] {taskinstance.py:1159} INFO - Dependencies all met for dep_context=non-requeueable deps ti=<TaskInstance: col_api_etl.extract_currency_conversion_rates manual__2023-11-01T23:05:52.250695+00:00 [queued]>
[2023-11-01T23:06:04.906+0000] {taskinstance.py:1159} INFO - Dependencies all met for dep_context=requeueable deps ti=<TaskInstance: col_api_etl.extract_currency_conversion_rates manual__2023-11-01T23:05:52.250695+00:00 [queued]>
[2023-11-01T23:06:04.908+0000] {taskinstance.py:1361} INFO - Starting attempt 1 of 1
[2023-11-01T23:06:04.952+0000] {taskinstance.py:1382} INFO - Executing <Task(PythonOperator): extract_currency_conversion_rates> on 2023-11-01 23:05:52.250695+00:00
[2023-11-01T23:06:04.962+0000] {clientserver.py:543} INFO - Closing down clientserver connection
[2023-11-01T23:06:04.962+0000] {standard_task_runner.py:57} INFO - Started process 937 to run task
[2023-11-01T23:06:04.969+0000] {standard_task_runner.py:84} INFO - Running: ['***', 'tasks', 'run', 'col_api_etl', 'extract_currency_conversion_rates', 'manual__2023-11-01T23:05:52.250695+00:00', '--job-id', '1158', '--raw', '--subdir', 'DAGS_FOLDER/col_api_etl.py', '--cfg-path', '/tmp/tmp7wckte3q']
[2023-11-01T23:06:04.972+0000] {standard_task_runner.py:85} INFO - Job 1158: Subtask extract_currency_conversion_rates
[2023-11-01T23:06:05.069+0000] {logging_mixin.py:151} INFO - Changing /opt/***/logs/dag_id=col_api_etl/run_id=manual__2023-11-01T23:05:52.250695+00:00/task_id=extract_currency_conversion_rates permission to 509
[2023-11-01T23:06:05.070+0000] {logging_mixin.py:151} INFO - Failed to change /opt/***/logs/dag_id=col_api_etl/run_id=manual__2023-11-01T23:05:52.250695+00:00/task_id=extract_currency_conversion_rates permission to 509: [Errno 1] Operation not permitted: '/opt/***/logs/dag_id=col_api_etl/run_id=manual__2023-11-01T23:05:52.250695+00:00/task_id=extract_currency_conversion_rates'
[2023-11-01T23:06:05.075+0000] {task_command.py:415} INFO - Running <TaskInstance: col_api_etl.extract_currency_conversion_rates manual__2023-11-01T23:05:52.250695+00:00 [running]> on host 65ec58942685
[2023-11-01T23:06:05.257+0000] {taskinstance.py:1660} INFO - Exporting env vars: AIRFLOW_CTX_DAG_OWNER='***' AIRFLOW_CTX_DAG_ID='col_api_etl' AIRFLOW_CTX_TASK_ID='extract_currency_conversion_rates' AIRFLOW_CTX_EXECUTION_DATE='2023-11-01T23:05:52.250695+00:00' AIRFLOW_CTX_TRY_NUMBER='1' AIRFLOW_CTX_DAG_RUN_ID='manual__2023-11-01T23:05:52.250695+00:00'
[2023-11-01T23:06:54.719+0000] {taskinstance.py:1943} ERROR - Task failed with exception
Traceback (most recent call last):
  File "/home/airflow/.local/lib/python3.8/site-packages/urllib3/connection.py", line 174, in _new_conn
    conn = connection.create_connection(
  File "/home/airflow/.local/lib/python3.8/site-packages/urllib3/util/connection.py", line 72, in create_connection
    for res in socket.getaddrinfo(host, port, family, socket.SOCK_STREAM):
  File "/usr/local/lib/python3.8/socket.py", line 918, in getaddrinfo
    for res in _socket.getaddrinfo(host, port, family, type, proto, flags):
socket.gaierror: [Errno -3] Temporary failure in name resolution

During handling of the above exception, another exception occurred:

Traceback (most recent call last):
  File "/home/airflow/.local/lib/python3.8/site-packages/botocore/httpsession.py", line 465, in send
    urllib_response = conn.urlopen(
  File "/home/airflow/.local/lib/python3.8/site-packages/urllib3/connectionpool.py", line 798, in urlopen
    retries = retries.increment(
  File "/home/airflow/.local/lib/python3.8/site-packages/urllib3/util/retry.py", line 525, in increment
    raise six.reraise(type(error), error, _stacktrace)
  File "/home/airflow/.local/lib/python3.8/site-packages/urllib3/packages/six.py", line 770, in reraise
    raise value
  File "/home/airflow/.local/lib/python3.8/site-packages/urllib3/connectionpool.py", line 714, in urlopen
    httplib_response = self._make_request(
  File "/home/airflow/.local/lib/python3.8/site-packages/urllib3/connectionpool.py", line 403, in _make_request
    self._validate_conn(conn)
  File "/home/airflow/.local/lib/python3.8/site-packages/urllib3/connectionpool.py", line 1053, in _validate_conn
    conn.connect()
  File "/home/airflow/.local/lib/python3.8/site-packages/urllib3/connection.py", line 363, in connect
    self.sock = conn = self._new_conn()
  File "/home/airflow/.local/lib/python3.8/site-packages/urllib3/connection.py", line 186, in _new_conn
    raise NewConnectionError(
urllib3.exceptions.NewConnectionError: <botocore.awsrequest.AWSHTTPSConnection object at 0x7fccdbd5a5b0>: Failed to establish a new connection: [Errno -3] Temporary failure in name resolution

During handling of the above exception, another exception occurred:

Traceback (most recent call last):
  File "/home/airflow/.local/lib/python3.8/site-packages/airflow/operators/python.py", line 192, in execute
    return_value = self.execute_callable()
  File "/home/airflow/.local/lib/python3.8/site-packages/airflow/operators/python.py", line 209, in execute_callable
    return self.python_callable(*self.op_args, **self.op_kwargs)
  File "/opt/airflow/dags/scripts/extraction.py", line 38, in extract_currency_conversion_rates
    put_data(file_prefix = 'currency_conversion_rates', data = currency_conversion_rates, bucket_type = 'raw')
  File "/opt/airflow/dags/utils/aws_utils.py", line 25, in put_data
    boto3_s3.put_object(Bucket = os.environ.get('S3_BUCKET_RAW'), Key = file_prefix + current_date, Body = data_json,
  File "/home/airflow/.local/lib/python3.8/site-packages/botocore/client.py", line 535, in _api_call
    return self._make_api_call(operation_name, kwargs)
  File "/home/airflow/.local/lib/python3.8/site-packages/botocore/client.py", line 963, in _make_api_call
    http, parsed_response = self._make_request(
  File "/home/airflow/.local/lib/python3.8/site-packages/botocore/client.py", line 986, in _make_request
    return self._endpoint.make_request(operation_model, request_dict)
  File "/home/airflow/.local/lib/python3.8/site-packages/botocore/endpoint.py", line 119, in make_request
    return self._send_request(request_dict, operation_model)
  File "/home/airflow/.local/lib/python3.8/site-packages/botocore/endpoint.py", line 202, in _send_request
    while self._needs_retry(
  File "/home/airflow/.local/lib/python3.8/site-packages/botocore/endpoint.py", line 354, in _needs_retry
    responses = self._event_emitter.emit(
  File "/home/airflow/.local/lib/python3.8/site-packages/botocore/hooks.py", line 412, in emit
    return self._emitter.emit(aliased_event_name, **kwargs)
  File "/home/airflow/.local/lib/python3.8/site-packages/botocore/hooks.py", line 256, in emit
    return self._emit(event_name, kwargs)
  File "/home/airflow/.local/lib/python3.8/site-packages/botocore/hooks.py", line 239, in _emit
    response = handler(**kwargs)
  File "/home/airflow/.local/lib/python3.8/site-packages/botocore/retryhandler.py", line 207, in __call__
    if self._checker(**checker_kwargs):
  File "/home/airflow/.local/lib/python3.8/site-packages/botocore/retryhandler.py", line 284, in __call__
    should_retry = self._should_retry(
  File "/home/airflow/.local/lib/python3.8/site-packages/botocore/retryhandler.py", line 320, in _should_retry
    return self._checker(attempt_number, response, caught_exception)
  File "/home/airflow/.local/lib/python3.8/site-packages/botocore/retryhandler.py", line 363, in __call__
    checker_response = checker(
  File "/home/airflow/.local/lib/python3.8/site-packages/botocore/retryhandler.py", line 247, in __call__
    return self._check_caught_exception(
  File "/home/airflow/.local/lib/python3.8/site-packages/botocore/retryhandler.py", line 416, in _check_caught_exception
    raise caught_exception
  File "/home/airflow/.local/lib/python3.8/site-packages/botocore/endpoint.py", line 281, in _do_get_response
    http_response = self._send(request)
  File "/home/airflow/.local/lib/python3.8/site-packages/botocore/endpoint.py", line 377, in _send
    return self.http_session.send(request)
  File "/home/airflow/.local/lib/python3.8/site-packages/botocore/httpsession.py", line 494, in send
    raise EndpointConnectionError(endpoint_url=request.url, error=e)
botocore.exceptions.EndpointConnectionError: Could not connect to the endpoint URL: "https://col-api-raw.s3.ap-southeast-1.amazonaws.com/currency_conversion_rates20231101"
[2023-11-01T23:06:54.758+0000] {taskinstance.py:1400} INFO - Marking task as FAILED. dag_id=col_api_etl, task_id=extract_currency_conversion_rates, execution_date=20231101T230552, start_date=20231101T230604, end_date=20231101T230654
[2023-11-01T23:06:54.783+0000] {standard_task_runner.py:104} ERROR - Failed to execute job 1158 for task extract_currency_conversion_rates (Could not connect to the endpoint URL: "https://col-api-raw.s3.ap-southeast-1.amazonaws.com/currency_conversion_rates20231101"; 937)
[2023-11-01T23:06:54.816+0000] {local_task_job_runner.py:228} INFO - Task exited with return code 1
