[2023-11-01T00:42:19.667+0000] {logging_mixin.py:151} INFO - Changing /opt/***/logs/dag_id=col_api_etl/run_id=manual__2023-11-01T00:42:04.411833+00:00/task_id=extract_numbeo_prices_from_city permission to 509
[2023-11-01T00:42:19.668+0000] {logging_mixin.py:151} INFO - Failed to change /opt/***/logs/dag_id=col_api_etl/run_id=manual__2023-11-01T00:42:04.411833+00:00/task_id=extract_numbeo_prices_from_city permission to 509: [Errno 1] Operation not permitted: '/opt/***/logs/dag_id=col_api_etl/run_id=manual__2023-11-01T00:42:04.411833+00:00/task_id=extract_numbeo_prices_from_city'
[2023-11-01T00:42:19.703+0000] {logging_mixin.py:151} INFO - Changing /opt/***/logs/dag_id=col_api_etl/run_id=manual__2023-11-01T00:42:04.411833+00:00/task_id=extract_numbeo_prices_from_city permission to 509
[2023-11-01T00:42:19.704+0000] {logging_mixin.py:151} INFO - Failed to change /opt/***/logs/dag_id=col_api_etl/run_id=manual__2023-11-01T00:42:04.411833+00:00/task_id=extract_numbeo_prices_from_city permission to 509: [Errno 1] Operation not permitted: '/opt/***/logs/dag_id=col_api_etl/run_id=manual__2023-11-01T00:42:04.411833+00:00/task_id=extract_numbeo_prices_from_city'
[2023-11-01T00:42:19.737+0000] {taskinstance.py:1149} INFO - Dependencies not met for <TaskInstance: col_api_etl.extract_numbeo_prices_from_city manual__2023-11-01T00:42:04.411833+00:00 [upstream_failed]>, dependency 'Task Instance State' FAILED: Task is in the 'upstream_failed' state.
[2023-11-01T00:42:19.746+0000] {taskinstance.py:1149} INFO - Dependencies not met for <TaskInstance: col_api_etl.extract_numbeo_prices_from_city manual__2023-11-01T00:42:04.411833+00:00 [upstream_failed]>, dependency 'Trigger Rule' FAILED: Task's trigger rule 'all_success' requires all upstream tasks to have succeeded, but found 1 non-success(es). upstream_states=_UpstreamTIStates(success=0, skipped=0, failed=1, upstream_failed=0, removed=0, done=1, success_setup=0, skipped_setup=0), upstream_task_ids={'extract_currency_conversion_rates'}
[2023-11-01T00:42:19.750+0000] {local_task_job_runner.py:154} INFO - Task is not able to be run
