[2023-10-29T01:06:10.150+0000] {logging_mixin.py:151} INFO - Changing /opt/***/logs/dag_id=col_api_etl/run_id=manual__2023-10-29T01:05:58.103122+00:00/task_id=extract_numbeo_prices_from_city permission to 509
[2023-10-29T01:06:10.151+0000] {logging_mixin.py:151} INFO - Failed to change /opt/***/logs/dag_id=col_api_etl/run_id=manual__2023-10-29T01:05:58.103122+00:00/task_id=extract_numbeo_prices_from_city permission to 509: [Errno 1] Operation not permitted: '/opt/***/logs/dag_id=col_api_etl/run_id=manual__2023-10-29T01:05:58.103122+00:00/task_id=extract_numbeo_prices_from_city'
[2023-10-29T01:06:10.176+0000] {logging_mixin.py:151} INFO - Changing /opt/***/logs/dag_id=col_api_etl/run_id=manual__2023-10-29T01:05:58.103122+00:00/task_id=extract_numbeo_prices_from_city permission to 509
[2023-10-29T01:06:10.177+0000] {logging_mixin.py:151} INFO - Failed to change /opt/***/logs/dag_id=col_api_etl/run_id=manual__2023-10-29T01:05:58.103122+00:00/task_id=extract_numbeo_prices_from_city permission to 509: [Errno 1] Operation not permitted: '/opt/***/logs/dag_id=col_api_etl/run_id=manual__2023-10-29T01:05:58.103122+00:00/task_id=extract_numbeo_prices_from_city'
[2023-10-29T01:06:10.206+0000] {taskinstance.py:1159} INFO - Dependencies all met for dep_context=non-requeueable deps ti=<TaskInstance: col_api_etl.extract_numbeo_prices_from_city manual__2023-10-29T01:05:58.103122+00:00 [queued]>
[2023-10-29T01:06:10.214+0000] {taskinstance.py:1159} INFO - Dependencies all met for dep_context=requeueable deps ti=<TaskInstance: col_api_etl.extract_numbeo_prices_from_city manual__2023-10-29T01:05:58.103122+00:00 [queued]>
[2023-10-29T01:06:10.214+0000] {taskinstance.py:1361} INFO - Starting attempt 1 of 2
[2023-10-29T01:06:10.225+0000] {taskinstance.py:1382} INFO - Executing <Task(PythonOperator): extract_numbeo_prices_from_city> on 2023-10-29 01:05:58.103122+00:00
[2023-10-29T01:06:10.230+0000] {standard_task_runner.py:57} INFO - Started process 4420 to run task
[2023-10-29T01:06:10.231+0000] {clientserver.py:543} INFO - Closing down clientserver connection
[2023-10-29T01:06:10.234+0000] {standard_task_runner.py:84} INFO - Running: ['***', 'tasks', 'run', 'col_api_etl', 'extract_numbeo_prices_from_city', 'manual__2023-10-29T01:05:58.103122+00:00', '--job-id', '1092', '--raw', '--subdir', 'DAGS_FOLDER/col_api_etl.py', '--cfg-path', '/tmp/tmpzeoe0d9q']
[2023-10-29T01:06:10.235+0000] {standard_task_runner.py:85} INFO - Job 1092: Subtask extract_numbeo_prices_from_city
[2023-10-29T01:06:10.271+0000] {logging_mixin.py:151} INFO - Changing /opt/***/logs/dag_id=col_api_etl/run_id=manual__2023-10-29T01:05:58.103122+00:00/task_id=extract_numbeo_prices_from_city permission to 509
[2023-10-29T01:06:10.271+0000] {logging_mixin.py:151} INFO - Failed to change /opt/***/logs/dag_id=col_api_etl/run_id=manual__2023-10-29T01:05:58.103122+00:00/task_id=extract_numbeo_prices_from_city permission to 509: [Errno 1] Operation not permitted: '/opt/***/logs/dag_id=col_api_etl/run_id=manual__2023-10-29T01:05:58.103122+00:00/task_id=extract_numbeo_prices_from_city'
[2023-10-29T01:06:10.273+0000] {task_command.py:415} INFO - Running <TaskInstance: col_api_etl.extract_numbeo_prices_from_city manual__2023-10-29T01:05:58.103122+00:00 [running]> on host ea85de3a6109
[2023-10-29T01:06:10.340+0000] {taskinstance.py:1660} INFO - Exporting env vars: AIRFLOW_CTX_DAG_OWNER='***' AIRFLOW_CTX_DAG_ID='col_api_etl' AIRFLOW_CTX_TASK_ID='extract_numbeo_prices_from_city' AIRFLOW_CTX_EXECUTION_DATE='2023-10-29T01:05:58.103122+00:00' AIRFLOW_CTX_TRY_NUMBER='1' AIRFLOW_CTX_DAG_RUN_ID='manual__2023-10-29T01:05:58.103122+00:00'
[2023-10-29T01:06:10.930+0000] {clientserver.py:505} INFO - Error while sending or receiving.
Traceback (most recent call last):
  File "/home/airflow/.local/lib/python3.8/site-packages/py4j/clientserver.py", line 503, in send_command
    self.socket.sendall(command.encode("utf-8"))
ConnectionResetError: [Errno 104] Connection reset by peer
[2023-10-29T01:06:10.932+0000] {clientserver.py:543} INFO - Closing down clientserver connection
[2023-10-29T01:06:10.933+0000] {java_gateway.py:1052} INFO - Exception while sending command.
Traceback (most recent call last):
  File "/home/airflow/.local/lib/python3.8/site-packages/py4j/clientserver.py", line 503, in send_command
    self.socket.sendall(command.encode("utf-8"))
ConnectionResetError: [Errno 104] Connection reset by peer

During handling of the above exception, another exception occurred:

Traceback (most recent call last):
  File "/home/airflow/.local/lib/python3.8/site-packages/py4j/java_gateway.py", line 1038, in send_command
    response = connection.send_command(command)
  File "/home/airflow/.local/lib/python3.8/site-packages/py4j/clientserver.py", line 506, in send_command
    raise Py4JNetworkError(
py4j.protocol.Py4JNetworkError: Error while sending
[2023-10-29T01:06:10.936+0000] {clientserver.py:543} INFO - Closing down clientserver connection
[2023-10-29T01:06:11.858+0000] {logging_mixin.py:151} INFO - Dubai
[2023-10-29T01:06:13.548+0000] {logging_mixin.py:151} INFO - Abu-Dhabi
[2023-10-29T01:06:15.280+0000] {logging_mixin.py:151} INFO - Sharjah
[2023-10-29T01:06:16.799+0000] {logging_mixin.py:151} INFO - Perth
[2023-10-29T01:06:18.446+0000] {logging_mixin.py:151} INFO - Melbourne
[2023-10-29T01:06:20.016+0000] {logging_mixin.py:151} INFO - Sydney
[2023-10-29T01:06:21.861+0000] {logging_mixin.py:151} INFO - Brisbane
[2023-10-29T01:06:23.512+0000] {logging_mixin.py:151} INFO - Hobart
[2023-10-29T01:06:24.749+0000] {logging_mixin.py:151} INFO - Adelaide
[2023-10-29T01:06:26.325+0000] {logging_mixin.py:151} INFO - Canberra
[2023-10-29T01:06:27.605+0000] {logging_mixin.py:151} INFO - Darwin
[2023-10-29T01:06:28.856+0000] {logging_mixin.py:151} INFO - Sarajevo
[2023-10-29T01:06:30.493+0000] {logging_mixin.py:151} INFO - Manama
[2023-10-29T01:06:32.062+0000] {logging_mixin.py:151} INFO - Sofia
[2023-10-29T01:06:33.682+0000] {logging_mixin.py:151} INFO - Sao-Paulo
[2023-10-29T01:06:35.521+0000] {logging_mixin.py:151} INFO - Rio-De-Janeiro
[2023-10-29T01:06:37.026+0000] {logging_mixin.py:151} INFO - Brasilia
[2023-10-29T01:06:38.312+0000] {logging_mixin.py:151} INFO - Toronto
[2023-10-29T01:06:39.945+0000] {logging_mixin.py:151} INFO - Montreal
[2023-10-29T01:06:41.591+0000] {logging_mixin.py:151} INFO - Vancouver
[2023-10-29T01:06:43.163+0000] {logging_mixin.py:151} INFO - Ottawa
[2023-10-29T01:06:44.702+0000] {logging_mixin.py:151} INFO - Calgary
[2023-10-29T01:06:46.212+0000] {logging_mixin.py:151} INFO - Edmonton
[2023-10-29T01:06:47.850+0000] {logging_mixin.py:151} INFO - Halifax
[2023-10-29T01:06:49.310+0000] {logging_mixin.py:151} INFO - Quebec-City
[2023-10-29T01:06:50.840+0000] {logging_mixin.py:151} INFO - Zurich
[2023-10-29T01:06:52.354+0000] {logging_mixin.py:151} INFO - Geneva
[2023-10-29T01:06:53.630+0000] {logging_mixin.py:151} INFO - Zug
[2023-10-29T01:06:54.839+0000] {logging_mixin.py:151} INFO - Basel
[2023-10-29T01:06:56.351+0000] {logging_mixin.py:151} INFO - Bern
[2023-10-29T01:06:58.067+0000] {logging_mixin.py:151} INFO - Lausanne
[2023-10-29T01:06:59.390+0000] {logging_mixin.py:151} INFO - Ticino
[2023-10-29T01:07:00.682+0000] {taskinstance.py:1943} ERROR - Task failed with exception
Traceback (most recent call last):
  File "/home/airflow/.local/lib/python3.8/site-packages/airflow/operators/python.py", line 192, in execute
    return_value = self.execute_callable()
  File "/home/airflow/.local/lib/python3.8/site-packages/airflow/operators/python.py", line 209, in execute_callable
    return self.python_callable(*self.op_args, **self.op_kwargs)
  File "/opt/airflow/dags/scripts/extraction.py", line 135, in extract_numbeo_prices_from_city
    prices_table = numbeo_prices_city_html.find('table', {'class': 'data_wide_table new_bar_table'}).find_all('tr')
AttributeError: 'NoneType' object has no attribute 'find_all'
[2023-10-29T01:07:00.695+0000] {taskinstance.py:1400} INFO - Marking task as UP_FOR_RETRY. dag_id=col_api_etl, task_id=extract_numbeo_prices_from_city, execution_date=20231029T010558, start_date=20231029T010610, end_date=20231029T010700
[2023-10-29T01:07:00.706+0000] {standard_task_runner.py:104} ERROR - Failed to execute job 1092 for task extract_numbeo_prices_from_city ('NoneType' object has no attribute 'find_all'; 4420)
[2023-10-29T01:07:00.735+0000] {local_task_job_runner.py:228} INFO - Task exited with return code 1
