[2023-11-04T03:38:50.423+0000] {logging_mixin.py:151} INFO - Changing /opt/***/logs/dag_id=col_api_etl/run_id=manual__2023-11-04T03:31:06.668121+00:00/task_id=merge_and_transform_homepurchase permission to 509
[2023-11-04T03:38:50.424+0000] {logging_mixin.py:151} INFO - Failed to change /opt/***/logs/dag_id=col_api_etl/run_id=manual__2023-11-04T03:31:06.668121+00:00/task_id=merge_and_transform_homepurchase permission to 509: [Errno 1] Operation not permitted: '/opt/***/logs/dag_id=col_api_etl/run_id=manual__2023-11-04T03:31:06.668121+00:00/task_id=merge_and_transform_homepurchase'
[2023-11-04T03:38:50.451+0000] {logging_mixin.py:151} INFO - Changing /opt/***/logs/dag_id=col_api_etl/run_id=manual__2023-11-04T03:31:06.668121+00:00/task_id=merge_and_transform_homepurchase permission to 509
[2023-11-04T03:38:50.452+0000] {logging_mixin.py:151} INFO - Failed to change /opt/***/logs/dag_id=col_api_etl/run_id=manual__2023-11-04T03:31:06.668121+00:00/task_id=merge_and_transform_homepurchase permission to 509: [Errno 1] Operation not permitted: '/opt/***/logs/dag_id=col_api_etl/run_id=manual__2023-11-04T03:31:06.668121+00:00/task_id=merge_and_transform_homepurchase'
[2023-11-04T03:38:50.484+0000] {taskinstance.py:1159} INFO - Dependencies all met for dep_context=non-requeueable deps ti=<TaskInstance: col_api_etl.merge_and_transform_homepurchase manual__2023-11-04T03:31:06.668121+00:00 [queued]>
[2023-11-04T03:38:50.492+0000] {taskinstance.py:1159} INFO - Dependencies all met for dep_context=requeueable deps ti=<TaskInstance: col_api_etl.merge_and_transform_homepurchase manual__2023-11-04T03:31:06.668121+00:00 [queued]>
[2023-11-04T03:38:50.493+0000] {taskinstance.py:1361} INFO - Starting attempt 1 of 1
[2023-11-04T03:38:50.506+0000] {taskinstance.py:1382} INFO - Executing <Task(PythonOperator): merge_and_transform_homepurchase> on 2023-11-04 03:31:06.668121+00:00
[2023-11-04T03:38:50.512+0000] {standard_task_runner.py:57} INFO - Started process 44121 to run task
[2023-11-04T03:38:50.512+0000] {clientserver.py:543} INFO - Closing down clientserver connection
[2023-11-04T03:38:50.515+0000] {standard_task_runner.py:84} INFO - Running: ['***', 'tasks', 'run', 'col_api_etl', 'merge_and_transform_homepurchase', 'manual__2023-11-04T03:31:06.668121+00:00', '--job-id', '1314', '--raw', '--subdir', 'DAGS_FOLDER/col_api_etl.py', '--cfg-path', '/tmp/tmpinycw1bk']
[2023-11-04T03:38:50.517+0000] {standard_task_runner.py:85} INFO - Job 1314: Subtask merge_and_transform_homepurchase
[2023-11-04T03:38:50.558+0000] {logging_mixin.py:151} INFO - Changing /opt/***/logs/dag_id=col_api_etl/run_id=manual__2023-11-04T03:31:06.668121+00:00/task_id=merge_and_transform_homepurchase permission to 509
[2023-11-04T03:38:50.558+0000] {logging_mixin.py:151} INFO - Failed to change /opt/***/logs/dag_id=col_api_etl/run_id=manual__2023-11-04T03:31:06.668121+00:00/task_id=merge_and_transform_homepurchase permission to 509: [Errno 1] Operation not permitted: '/opt/***/logs/dag_id=col_api_etl/run_id=manual__2023-11-04T03:31:06.668121+00:00/task_id=merge_and_transform_homepurchase'
[2023-11-04T03:38:50.561+0000] {task_command.py:415} INFO - Running <TaskInstance: col_api_etl.merge_and_transform_homepurchase manual__2023-11-04T03:31:06.668121+00:00 [running]> on host 0bcf85c4b011
[2023-11-04T03:38:50.775+0000] {taskinstance.py:1660} INFO - Exporting env vars: AIRFLOW_CTX_DAG_OWNER='***' AIRFLOW_CTX_DAG_ID='col_api_etl' AIRFLOW_CTX_TASK_ID='merge_and_transform_homepurchase' AIRFLOW_CTX_EXECUTION_DATE='2023-11-04T03:31:06.668121+00:00' AIRFLOW_CTX_TRY_NUMBER='1' AIRFLOW_CTX_DAG_RUN_ID='manual__2023-11-04T03:31:06.668121+00:00'
[2023-11-04T03:38:51.210+0000] {clientserver.py:505} INFO - Error while sending or receiving.
Traceback (most recent call last):
  File "/home/airflow/.local/lib/python3.8/site-packages/py4j/clientserver.py", line 503, in send_command
    self.socket.sendall(command.encode("utf-8"))
ConnectionResetError: [Errno 104] Connection reset by peer
[2023-11-04T03:38:51.212+0000] {clientserver.py:543} INFO - Closing down clientserver connection
[2023-11-04T03:38:51.212+0000] {java_gateway.py:1052} INFO - Exception while sending command.
Traceback (most recent call last):
  File "/home/airflow/.local/lib/python3.8/site-packages/py4j/clientserver.py", line 503, in send_command
    self.socket.sendall(command.encode("utf-8"))
ConnectionResetError: [Errno 104] Connection reset by peer

During handling of the above exception, another exception occurred:

Traceback (most recent call last):
  File "/home/airflow/.local/lib/python3.8/site-packages/py4j/java_gateway.py", line 1038, in send_command
    response = connection.send_command(command)
  File "/home/airflow/.local/lib/python3.8/site-packages/py4j/clientserver.py", line 506, in send_command
    raise Py4JNetworkError(
py4j.protocol.Py4JNetworkError: Error while sending
[2023-11-04T03:38:51.215+0000] {clientserver.py:543} INFO - Closing down clientserver connection
[2023-11-04T03:38:58.599+0000] {logging_mixin.py:151} INFO - +----+-----------------+----------------------+-----------------+
|City|Property Location|Price per Square Meter|Mortgage Interest|
+----+-----------------+----------------------+-----------------+
+----+-----------------+----------------------+-----------------+
[2023-11-04T03:39:01.426+0000] {python.py:194} INFO - Done. Returned value was: None
[2023-11-04T03:39:01.437+0000] {taskinstance.py:1400} INFO - Marking task as SUCCESS. dag_id=col_api_etl, task_id=merge_and_transform_homepurchase, execution_date=20231104T033106, start_date=20231104T033850, end_date=20231104T033901
[2023-11-04T03:39:01.479+0000] {local_task_job_runner.py:228} INFO - Task exited with return code 0
