[2023-11-25T08:47:46.136+0000] {taskinstance.py:1159} INFO - Dependencies all met for dep_context=non-requeueable deps ti=<TaskInstance: col_api_etl.merge_and_transform_rent manual__2023-11-25T08:39:52.868395+00:00 [queued]>
[2023-11-25T08:47:46.151+0000] {taskinstance.py:1159} INFO - Dependencies all met for dep_context=requeueable deps ti=<TaskInstance: col_api_etl.merge_and_transform_rent manual__2023-11-25T08:39:52.868395+00:00 [queued]>
[2023-11-25T08:47:46.151+0000] {taskinstance.py:1361} INFO - Starting attempt 2 of 2
[2023-11-25T08:47:46.176+0000] {taskinstance.py:1382} INFO - Executing <Task(PythonOperator): merge_and_transform_rent> on 2023-11-25 08:39:52.868395+00:00
[2023-11-25T08:47:46.184+0000] {standard_task_runner.py:57} INFO - Started process 11557 to run task
[2023-11-25T08:47:46.196+0000] {clientserver.py:543} INFO - Closing down clientserver connection
[2023-11-25T08:47:46.203+0000] {standard_task_runner.py:84} INFO - Running: ['***', 'tasks', 'run', 'col_api_etl', 'merge_and_transform_rent', 'manual__2023-11-25T08:39:52.868395+00:00', '--job-id', '38', '--raw', '--subdir', 'DAGS_FOLDER/col_api_etl.py', '--cfg-path', '/tmp/tmpgc12_izs']
[2023-11-25T08:47:46.205+0000] {standard_task_runner.py:85} INFO - Job 38: Subtask merge_and_transform_rent
[2023-11-25T08:47:46.281+0000] {task_command.py:415} INFO - Running <TaskInstance: col_api_etl.merge_and_transform_rent manual__2023-11-25T08:39:52.868395+00:00 [running]> on host 9b6b24afef42
[2023-11-25T08:47:46.296+0000] {clientserver.py:505} INFO - Error while sending or receiving.
Traceback (most recent call last):
  File "/home/airflow/.local/lib/python3.8/site-packages/py4j/clientserver.py", line 503, in send_command
    self.socket.sendall(command.encode("utf-8"))
ConnectionResetError: [Errno 104] Connection reset by peer
[2023-11-25T08:47:46.298+0000] {clientserver.py:543} INFO - Closing down clientserver connection
[2023-11-25T08:47:46.298+0000] {java_gateway.py:1052} INFO - Exception while sending command.
Traceback (most recent call last):
  File "/home/airflow/.local/lib/python3.8/site-packages/py4j/clientserver.py", line 503, in send_command
    self.socket.sendall(command.encode("utf-8"))
ConnectionResetError: [Errno 104] Connection reset by peer

During handling of the above exception, another exception occurred:

Traceback (most recent call last):
  File "/home/airflow/.local/lib/python3.8/site-packages/py4j/java_gateway.py", line 1038, in send_command
    response = connection.send_command(command)
  File "/home/airflow/.local/lib/python3.8/site-packages/py4j/clientserver.py", line 506, in send_command
    raise Py4JNetworkError(
py4j.protocol.Py4JNetworkError: Error while sending
[2023-11-25T08:47:46.302+0000] {clientserver.py:543} INFO - Closing down clientserver connection
[2023-11-25T08:47:46.633+0000] {taskinstance.py:1660} INFO - Exporting env vars: AIRFLOW_CTX_DAG_OWNER='***' AIRFLOW_CTX_DAG_ID='col_api_etl' AIRFLOW_CTX_TASK_ID='merge_and_transform_rent' AIRFLOW_CTX_EXECUTION_DATE='2023-11-25T08:39:52.868395+00:00' AIRFLOW_CTX_TRY_NUMBER='2' AIRFLOW_CTX_DAG_RUN_ID='manual__2023-11-25T08:39:52.868395+00:00'
[2023-11-25T08:47:54.642+0000] {taskinstance.py:1943} ERROR - Task failed with exception
Traceback (most recent call last):
  File "/home/airflow/.local/lib/python3.8/site-packages/airflow/operators/python.py", line 192, in execute
    return_value = self.execute_callable()
  File "/home/airflow/.local/lib/python3.8/site-packages/airflow/operators/python.py", line 209, in execute_callable
    return self.python_callable(*self.op_args, **self.op_kwargs)
  File "/opt/airflow/dags/scripts/pyspark.py", line 133, in merge_and_transform_rent
    numbeo_price_info = [{**row.asDict(), 'Monthly Price': round(row['Monthly Price'], 2)} for row in numbeo_price_info_df_filtered.collect()]
  File "/opt/airflow/dags/scripts/pyspark.py", line 133, in <listcomp>
    numbeo_price_info = [{**row.asDict(), 'Monthly Price': round(row['Monthly Price'], 2)} for row in numbeo_price_info_df_filtered.collect()]
TypeError: type NoneType doesn't define __round__ method
[2023-11-25T08:47:54.657+0000] {taskinstance.py:1400} INFO - Marking task as FAILED. dag_id=col_api_etl, task_id=merge_and_transform_rent, execution_date=20231125T083952, start_date=20231125T084746, end_date=20231125T084754
[2023-11-25T08:47:54.671+0000] {standard_task_runner.py:104} ERROR - Failed to execute job 38 for task merge_and_transform_rent (type NoneType doesn't define __round__ method; 11557)
[2023-11-25T08:47:54.724+0000] {local_task_job_runner.py:228} INFO - Task exited with return code 1
