[2023-10-29T02:20:40.296+0000] {logging_mixin.py:151} INFO - Changing /opt/***/logs/dag_id=col_api_etl/run_id=manual__2023-10-29T02:20:29.147230+00:00/task_id=extract_numbeo_prices_from_city permission to 509
[2023-10-29T02:20:40.297+0000] {logging_mixin.py:151} INFO - Failed to change /opt/***/logs/dag_id=col_api_etl/run_id=manual__2023-10-29T02:20:29.147230+00:00/task_id=extract_numbeo_prices_from_city permission to 509: [Errno 1] Operation not permitted: '/opt/***/logs/dag_id=col_api_etl/run_id=manual__2023-10-29T02:20:29.147230+00:00/task_id=extract_numbeo_prices_from_city'
[2023-10-29T02:20:40.322+0000] {logging_mixin.py:151} INFO - Changing /opt/***/logs/dag_id=col_api_etl/run_id=manual__2023-10-29T02:20:29.147230+00:00/task_id=extract_numbeo_prices_from_city permission to 509
[2023-10-29T02:20:40.322+0000] {logging_mixin.py:151} INFO - Failed to change /opt/***/logs/dag_id=col_api_etl/run_id=manual__2023-10-29T02:20:29.147230+00:00/task_id=extract_numbeo_prices_from_city permission to 509: [Errno 1] Operation not permitted: '/opt/***/logs/dag_id=col_api_etl/run_id=manual__2023-10-29T02:20:29.147230+00:00/task_id=extract_numbeo_prices_from_city'
[2023-10-29T02:20:40.352+0000] {taskinstance.py:1159} INFO - Dependencies all met for dep_context=non-requeueable deps ti=<TaskInstance: col_api_etl.extract_numbeo_prices_from_city manual__2023-10-29T02:20:29.147230+00:00 [queued]>
[2023-10-29T02:20:40.360+0000] {taskinstance.py:1159} INFO - Dependencies all met for dep_context=requeueable deps ti=<TaskInstance: col_api_etl.extract_numbeo_prices_from_city manual__2023-10-29T02:20:29.147230+00:00 [queued]>
[2023-10-29T02:20:40.361+0000] {taskinstance.py:1361} INFO - Starting attempt 1 of 2
[2023-10-29T02:20:40.373+0000] {taskinstance.py:1382} INFO - Executing <Task(PythonOperator): extract_numbeo_prices_from_city> on 2023-10-29 02:20:29.147230+00:00
[2023-10-29T02:20:40.378+0000] {standard_task_runner.py:57} INFO - Started process 26866 to run task
[2023-10-29T02:20:40.378+0000] {clientserver.py:543} INFO - Closing down clientserver connection
[2023-10-29T02:20:40.382+0000] {standard_task_runner.py:84} INFO - Running: ['***', 'tasks', 'run', 'col_api_etl', 'extract_numbeo_prices_from_city', 'manual__2023-10-29T02:20:29.147230+00:00', '--job-id', '1098', '--raw', '--subdir', 'DAGS_FOLDER/col_api_etl.py', '--cfg-path', '/tmp/tmp5l022mmp']
[2023-10-29T02:20:40.383+0000] {standard_task_runner.py:85} INFO - Job 1098: Subtask extract_numbeo_prices_from_city
[2023-10-29T02:20:40.419+0000] {logging_mixin.py:151} INFO - Changing /opt/***/logs/dag_id=col_api_etl/run_id=manual__2023-10-29T02:20:29.147230+00:00/task_id=extract_numbeo_prices_from_city permission to 509
[2023-10-29T02:20:40.420+0000] {logging_mixin.py:151} INFO - Failed to change /opt/***/logs/dag_id=col_api_etl/run_id=manual__2023-10-29T02:20:29.147230+00:00/task_id=extract_numbeo_prices_from_city permission to 509: [Errno 1] Operation not permitted: '/opt/***/logs/dag_id=col_api_etl/run_id=manual__2023-10-29T02:20:29.147230+00:00/task_id=extract_numbeo_prices_from_city'
[2023-10-29T02:20:40.422+0000] {task_command.py:415} INFO - Running <TaskInstance: col_api_etl.extract_numbeo_prices_from_city manual__2023-10-29T02:20:29.147230+00:00 [running]> on host ea85de3a6109
[2023-10-29T02:20:40.488+0000] {taskinstance.py:1660} INFO - Exporting env vars: AIRFLOW_CTX_DAG_OWNER='***' AIRFLOW_CTX_DAG_ID='col_api_etl' AIRFLOW_CTX_TASK_ID='extract_numbeo_prices_from_city' AIRFLOW_CTX_EXECUTION_DATE='2023-10-29T02:20:29.147230+00:00' AIRFLOW_CTX_TRY_NUMBER='1' AIRFLOW_CTX_DAG_RUN_ID='manual__2023-10-29T02:20:29.147230+00:00'
[2023-10-29T02:20:41.195+0000] {clientserver.py:505} INFO - Error while sending or receiving.
Traceback (most recent call last):
  File "/home/airflow/.local/lib/python3.8/site-packages/py4j/clientserver.py", line 503, in send_command
    self.socket.sendall(command.encode("utf-8"))
ConnectionResetError: [Errno 104] Connection reset by peer
[2023-10-29T02:20:41.197+0000] {clientserver.py:543} INFO - Closing down clientserver connection
[2023-10-29T02:20:41.198+0000] {java_gateway.py:1052} INFO - Exception while sending command.
Traceback (most recent call last):
  File "/home/airflow/.local/lib/python3.8/site-packages/py4j/clientserver.py", line 503, in send_command
    self.socket.sendall(command.encode("utf-8"))
ConnectionResetError: [Errno 104] Connection reset by peer

During handling of the above exception, another exception occurred:

Traceback (most recent call last):
  File "/home/airflow/.local/lib/python3.8/site-packages/py4j/java_gateway.py", line 1038, in send_command
    response = connection.send_command(command)
  File "/home/airflow/.local/lib/python3.8/site-packages/py4j/clientserver.py", line 506, in send_command
    raise Py4JNetworkError(
py4j.protocol.Py4JNetworkError: Error while sending
[2023-10-29T02:20:41.200+0000] {clientserver.py:543} INFO - Closing down clientserver connection
[2023-10-29T02:20:42.045+0000] {logging_mixin.py:151} INFO - Dubai
[2023-10-29T02:20:47.874+0000] {logging_mixin.py:151} INFO - Abu-Dhabi
[2023-10-29T02:20:53.370+0000] {logging_mixin.py:151} INFO - Sharjah
[2023-10-29T02:20:58.878+0000] {logging_mixin.py:151} INFO - Perth
[2023-10-29T02:21:04.495+0000] {logging_mixin.py:151} INFO - Melbourne
[2023-10-29T02:21:10.007+0000] {logging_mixin.py:151} INFO - Sydney
[2023-10-29T02:21:15.688+0000] {logging_mixin.py:151} INFO - Brisbane
[2023-10-29T02:21:21.228+0000] {logging_mixin.py:151} INFO - Hobart
[2023-10-29T02:21:26.470+0000] {logging_mixin.py:151} INFO - Adelaide
[2023-10-29T02:21:32.053+0000] {logging_mixin.py:151} INFO - Canberra
[2023-10-29T02:21:37.296+0000] {logging_mixin.py:151} INFO - Darwin
[2023-10-29T02:21:42.524+0000] {logging_mixin.py:151} INFO - Sarajevo
[2023-10-29T02:21:48.131+0000] {logging_mixin.py:151} INFO - Manama
[2023-10-29T02:21:53.381+0000] {logging_mixin.py:151} INFO - Sofia
[2023-10-29T02:21:59.565+0000] {logging_mixin.py:151} INFO - Sao-Paulo
[2023-10-29T02:22:05.270+0000] {logging_mixin.py:151} INFO - Rio-De-Janeiro
[2023-10-29T02:22:10.766+0000] {logging_mixin.py:151} INFO - Brasilia
[2023-10-29T02:22:16.532+0000] {logging_mixin.py:151} INFO - Toronto
[2023-10-29T02:22:22.363+0000] {logging_mixin.py:151} INFO - Montreal
[2023-10-29T02:22:28.148+0000] {logging_mixin.py:151} INFO - Vancouver
[2023-10-29T02:22:33.654+0000] {logging_mixin.py:151} INFO - Ottawa
[2023-10-29T02:22:39.170+0000] {logging_mixin.py:151} INFO - Calgary
[2023-10-29T02:22:44.682+0000] {logging_mixin.py:151} INFO - Edmonton
[2023-10-29T02:22:50.351+0000] {logging_mixin.py:151} INFO - Halifax
[2023-10-29T02:22:55.862+0000] {logging_mixin.py:151} INFO - Quebec-City
[2023-10-29T02:23:01.356+0000] {logging_mixin.py:151} INFO - Zurich
[2023-10-29T02:23:06.847+0000] {logging_mixin.py:151} INFO - Geneva
[2023-10-29T02:23:12.753+0000] {logging_mixin.py:151} INFO - Zug
[2023-10-29T02:23:17.997+0000] {logging_mixin.py:151} INFO - Basel
[2023-10-29T02:23:23.500+0000] {logging_mixin.py:151} INFO - Bern
[2023-10-29T02:23:29.082+0000] {logging_mixin.py:151} INFO - Lausanne
[2023-10-29T02:23:34.341+0000] {logging_mixin.py:151} INFO - Lugano
[2023-10-29T02:23:40.017+0000] {logging_mixin.py:151} INFO - Vaduz
[2023-10-29T02:23:45.271+0000] {logging_mixin.py:151} INFO - Santiago
[2023-10-29T02:23:51.010+0000] {logging_mixin.py:151} INFO - Chongqing
[2023-10-29T02:23:56.246+0000] {logging_mixin.py:151} INFO - Shanghai
[2023-10-29T02:24:03.207+0000] {logging_mixin.py:151} INFO - Beijing
[2023-10-29T02:24:09.021+0000] {logging_mixin.py:151} INFO - Chendgu
[2023-10-29T02:24:14.227+0000] {taskinstance.py:1943} ERROR - Task failed with exception
Traceback (most recent call last):
  File "/home/airflow/.local/lib/python3.8/site-packages/airflow/operators/python.py", line 192, in execute
    return_value = self.execute_callable()
  File "/home/airflow/.local/lib/python3.8/site-packages/airflow/operators/python.py", line 209, in execute_callable
    return self.python_callable(*self.op_args, **self.op_kwargs)
  File "/opt/airflow/dags/scripts/extraction.py", line 141, in extract_numbeo_prices_from_city
    prices_table = numbeo_prices_city_html.find('table', {'class': 'data_wide_table new_bar_table'}).find_all('tr')
AttributeError: 'NoneType' object has no attribute 'find_all'
[2023-10-29T02:24:14.242+0000] {taskinstance.py:1400} INFO - Marking task as UP_FOR_RETRY. dag_id=col_api_etl, task_id=extract_numbeo_prices_from_city, execution_date=20231029T022029, start_date=20231029T022040, end_date=20231029T022414
[2023-10-29T02:24:14.254+0000] {standard_task_runner.py:104} ERROR - Failed to execute job 1098 for task extract_numbeo_prices_from_city ('NoneType' object has no attribute 'find_all'; 26866)
[2023-10-29T02:24:14.291+0000] {local_task_job_runner.py:228} INFO - Task exited with return code 1
