[2023-10-29T02:24:47.629+0000] {logging_mixin.py:151} INFO - Changing /opt/***/logs/dag_id=col_api_etl/run_id=manual__2023-10-29T02:20:29.147230+00:00/task_id=extract_numbeo_prices_from_city permission to 509
[2023-10-29T02:24:47.630+0000] {logging_mixin.py:151} INFO - Failed to change /opt/***/logs/dag_id=col_api_etl/run_id=manual__2023-10-29T02:20:29.147230+00:00/task_id=extract_numbeo_prices_from_city permission to 509: [Errno 1] Operation not permitted: '/opt/***/logs/dag_id=col_api_etl/run_id=manual__2023-10-29T02:20:29.147230+00:00/task_id=extract_numbeo_prices_from_city'
[2023-10-29T02:24:47.655+0000] {logging_mixin.py:151} INFO - Changing /opt/***/logs/dag_id=col_api_etl/run_id=manual__2023-10-29T02:20:29.147230+00:00/task_id=extract_numbeo_prices_from_city permission to 509
[2023-10-29T02:24:47.656+0000] {logging_mixin.py:151} INFO - Failed to change /opt/***/logs/dag_id=col_api_etl/run_id=manual__2023-10-29T02:20:29.147230+00:00/task_id=extract_numbeo_prices_from_city permission to 509: [Errno 1] Operation not permitted: '/opt/***/logs/dag_id=col_api_etl/run_id=manual__2023-10-29T02:20:29.147230+00:00/task_id=extract_numbeo_prices_from_city'
[2023-10-29T02:24:47.685+0000] {taskinstance.py:1159} INFO - Dependencies all met for dep_context=non-requeueable deps ti=<TaskInstance: col_api_etl.extract_numbeo_prices_from_city manual__2023-10-29T02:20:29.147230+00:00 [queued]>
[2023-10-29T02:24:47.694+0000] {taskinstance.py:1159} INFO - Dependencies all met for dep_context=requeueable deps ti=<TaskInstance: col_api_etl.extract_numbeo_prices_from_city manual__2023-10-29T02:20:29.147230+00:00 [queued]>
[2023-10-29T02:24:47.695+0000] {taskinstance.py:1361} INFO - Starting attempt 2 of 2
[2023-10-29T02:24:47.706+0000] {taskinstance.py:1382} INFO - Executing <Task(PythonOperator): extract_numbeo_prices_from_city> on 2023-10-29 02:20:29.147230+00:00
[2023-10-29T02:24:47.711+0000] {clientserver.py:543} INFO - Closing down clientserver connection
[2023-10-29T02:24:47.711+0000] {standard_task_runner.py:57} INFO - Started process 28130 to run task
[2023-10-29T02:24:47.714+0000] {standard_task_runner.py:84} INFO - Running: ['***', 'tasks', 'run', 'col_api_etl', 'extract_numbeo_prices_from_city', 'manual__2023-10-29T02:20:29.147230+00:00', '--job-id', '1099', '--raw', '--subdir', 'DAGS_FOLDER/col_api_etl.py', '--cfg-path', '/tmp/tmpear3xwue']
[2023-10-29T02:24:47.717+0000] {standard_task_runner.py:85} INFO - Job 1099: Subtask extract_numbeo_prices_from_city
[2023-10-29T02:24:47.754+0000] {logging_mixin.py:151} INFO - Changing /opt/***/logs/dag_id=col_api_etl/run_id=manual__2023-10-29T02:20:29.147230+00:00/task_id=extract_numbeo_prices_from_city permission to 509
[2023-10-29T02:24:47.755+0000] {logging_mixin.py:151} INFO - Failed to change /opt/***/logs/dag_id=col_api_etl/run_id=manual__2023-10-29T02:20:29.147230+00:00/task_id=extract_numbeo_prices_from_city permission to 509: [Errno 1] Operation not permitted: '/opt/***/logs/dag_id=col_api_etl/run_id=manual__2023-10-29T02:20:29.147230+00:00/task_id=extract_numbeo_prices_from_city'
[2023-10-29T02:24:47.757+0000] {task_command.py:415} INFO - Running <TaskInstance: col_api_etl.extract_numbeo_prices_from_city manual__2023-10-29T02:20:29.147230+00:00 [running]> on host ea85de3a6109
[2023-10-29T02:24:47.828+0000] {taskinstance.py:1660} INFO - Exporting env vars: AIRFLOW_CTX_DAG_OWNER='***' AIRFLOW_CTX_DAG_ID='col_api_etl' AIRFLOW_CTX_TASK_ID='extract_numbeo_prices_from_city' AIRFLOW_CTX_EXECUTION_DATE='2023-10-29T02:20:29.147230+00:00' AIRFLOW_CTX_TRY_NUMBER='2' AIRFLOW_CTX_DAG_RUN_ID='manual__2023-10-29T02:20:29.147230+00:00'
[2023-10-29T02:24:48.450+0000] {clientserver.py:505} INFO - Error while sending or receiving.
Traceback (most recent call last):
  File "/home/airflow/.local/lib/python3.8/site-packages/py4j/clientserver.py", line 503, in send_command
    self.socket.sendall(command.encode("utf-8"))
ConnectionResetError: [Errno 104] Connection reset by peer
[2023-10-29T02:24:48.452+0000] {clientserver.py:543} INFO - Closing down clientserver connection
[2023-10-29T02:24:48.453+0000] {java_gateway.py:1052} INFO - Exception while sending command.
Traceback (most recent call last):
  File "/home/airflow/.local/lib/python3.8/site-packages/py4j/clientserver.py", line 503, in send_command
    self.socket.sendall(command.encode("utf-8"))
ConnectionResetError: [Errno 104] Connection reset by peer

During handling of the above exception, another exception occurred:

Traceback (most recent call last):
  File "/home/airflow/.local/lib/python3.8/site-packages/py4j/java_gateway.py", line 1038, in send_command
    response = connection.send_command(command)
  File "/home/airflow/.local/lib/python3.8/site-packages/py4j/clientserver.py", line 506, in send_command
    raise Py4JNetworkError(
py4j.protocol.Py4JNetworkError: Error while sending
[2023-10-29T02:24:48.455+0000] {clientserver.py:543} INFO - Closing down clientserver connection
[2023-10-29T02:24:49.421+0000] {logging_mixin.py:151} INFO - Dubai
[2023-10-29T02:24:54.973+0000] {logging_mixin.py:151} INFO - Abu-Dhabi
[2023-10-29T02:25:00.528+0000] {logging_mixin.py:151} INFO - Sharjah
[2023-10-29T02:25:09.057+0000] {logging_mixin.py:151} INFO - Perth
[2023-10-29T02:25:14.628+0000] {logging_mixin.py:151} INFO - Melbourne
[2023-10-29T02:25:20.146+0000] {logging_mixin.py:151} INFO - Sydney
[2023-10-29T02:25:25.853+0000] {logging_mixin.py:151} INFO - Brisbane
[2023-10-29T02:25:31.380+0000] {logging_mixin.py:151} INFO - Hobart
[2023-10-29T02:25:36.639+0000] {logging_mixin.py:151} INFO - Adelaide
[2023-10-29T02:25:42.149+0000] {logging_mixin.py:151} INFO - Canberra
[2023-10-29T02:25:47.389+0000] {logging_mixin.py:151} INFO - Darwin
[2023-10-29T02:25:52.620+0000] {logging_mixin.py:151} INFO - Sarajevo
[2023-10-29T02:25:58.136+0000] {logging_mixin.py:151} INFO - Manama
[2023-10-29T02:26:03.372+0000] {logging_mixin.py:151} INFO - Sofia
[2023-10-29T02:26:09.176+0000] {logging_mixin.py:151} INFO - Sao-Paulo
[2023-10-29T02:26:14.927+0000] {logging_mixin.py:151} INFO - Rio-De-Janeiro
[2023-10-29T02:26:20.567+0000] {logging_mixin.py:151} INFO - Brasilia
[2023-10-29T02:26:25.817+0000] {logging_mixin.py:151} INFO - Toronto
[2023-10-29T02:26:31.789+0000] {logging_mixin.py:151} INFO - Montreal
[2023-10-29T02:26:37.590+0000] {logging_mixin.py:151} INFO - Vancouver
[2023-10-29T02:26:43.123+0000] {logging_mixin.py:151} INFO - Ottawa
[2023-10-29T02:26:48.604+0000] {logging_mixin.py:151} INFO - Calgary
[2023-10-29T02:26:54.144+0000] {logging_mixin.py:151} INFO - Edmonton
[2023-10-29T02:26:59.802+0000] {logging_mixin.py:151} INFO - Halifax
[2023-10-29T02:27:05.307+0000] {logging_mixin.py:151} INFO - Quebec-City
[2023-10-29T02:27:10.887+0000] {logging_mixin.py:151} INFO - Zurich
[2023-10-29T02:27:16.414+0000] {logging_mixin.py:151} INFO - Geneva
[2023-10-29T02:27:21.918+0000] {logging_mixin.py:151} INFO - Zug
[2023-10-29T02:27:27.204+0000] {logging_mixin.py:151} INFO - Basel
[2023-10-29T02:27:32.718+0000] {logging_mixin.py:151} INFO - Bern
[2023-10-29T02:27:37.968+0000] {logging_mixin.py:151} INFO - Lausanne
[2023-10-29T02:27:43.518+0000] {logging_mixin.py:151} INFO - Lugano
[2023-10-29T02:27:49.031+0000] {logging_mixin.py:151} INFO - Vaduz
[2023-10-29T02:27:54.283+0000] {logging_mixin.py:151} INFO - Santiago
[2023-10-29T02:27:59.827+0000] {logging_mixin.py:151} INFO - Chongqing
[2023-10-29T02:28:05.095+0000] {logging_mixin.py:151} INFO - Shanghai
[2023-10-29T02:28:10.619+0000] {logging_mixin.py:151} INFO - Beijing
[2023-10-29T02:28:16.423+0000] {logging_mixin.py:151} INFO - Chendgu
[2023-10-29T02:28:21.764+0000] {taskinstance.py:1943} ERROR - Task failed with exception
Traceback (most recent call last):
  File "/home/airflow/.local/lib/python3.8/site-packages/airflow/operators/python.py", line 192, in execute
    return_value = self.execute_callable()
  File "/home/airflow/.local/lib/python3.8/site-packages/airflow/operators/python.py", line 209, in execute_callable
    return self.python_callable(*self.op_args, **self.op_kwargs)
  File "/opt/airflow/dags/scripts/extraction.py", line 141, in extract_numbeo_prices_from_city
    prices_table = numbeo_prices_city_html.find('table', {'class': 'data_wide_table new_bar_table'}).find_all('tr')
AttributeError: 'NoneType' object has no attribute 'find_all'
[2023-10-29T02:28:21.780+0000] {taskinstance.py:1400} INFO - Marking task as FAILED. dag_id=col_api_etl, task_id=extract_numbeo_prices_from_city, execution_date=20231029T022029, start_date=20231029T022447, end_date=20231029T022821
[2023-10-29T02:28:21.795+0000] {standard_task_runner.py:104} ERROR - Failed to execute job 1099 for task extract_numbeo_prices_from_city ('NoneType' object has no attribute 'find_all'; 28130)
[2023-10-29T02:28:21.832+0000] {local_task_job_runner.py:228} INFO - Task exited with return code 1
