[2023-11-04T03:38:36.841+0000] {logging_mixin.py:151} INFO - Changing /opt/***/logs/dag_id=col_api_etl/run_id=manual__2023-11-04T03:31:06.668121+00:00/task_id=merge_locations_with_currencies permission to 509
[2023-11-04T03:38:36.842+0000] {logging_mixin.py:151} INFO - Failed to change /opt/***/logs/dag_id=col_api_etl/run_id=manual__2023-11-04T03:31:06.668121+00:00/task_id=merge_locations_with_currencies permission to 509: [Errno 1] Operation not permitted: '/opt/***/logs/dag_id=col_api_etl/run_id=manual__2023-11-04T03:31:06.668121+00:00/task_id=merge_locations_with_currencies'
[2023-11-04T03:38:36.881+0000] {logging_mixin.py:151} INFO - Changing /opt/***/logs/dag_id=col_api_etl/run_id=manual__2023-11-04T03:31:06.668121+00:00/task_id=merge_locations_with_currencies permission to 509
[2023-11-04T03:38:36.881+0000] {logging_mixin.py:151} INFO - Failed to change /opt/***/logs/dag_id=col_api_etl/run_id=manual__2023-11-04T03:31:06.668121+00:00/task_id=merge_locations_with_currencies permission to 509: [Errno 1] Operation not permitted: '/opt/***/logs/dag_id=col_api_etl/run_id=manual__2023-11-04T03:31:06.668121+00:00/task_id=merge_locations_with_currencies'
[2023-11-04T03:38:36.915+0000] {taskinstance.py:1159} INFO - Dependencies all met for dep_context=non-requeueable deps ti=<TaskInstance: col_api_etl.merge_locations_with_currencies manual__2023-11-04T03:31:06.668121+00:00 [queued]>
[2023-11-04T03:38:36.923+0000] {taskinstance.py:1159} INFO - Dependencies all met for dep_context=requeueable deps ti=<TaskInstance: col_api_etl.merge_locations_with_currencies manual__2023-11-04T03:31:06.668121+00:00 [queued]>
[2023-11-04T03:38:36.923+0000] {taskinstance.py:1361} INFO - Starting attempt 1 of 1
[2023-11-04T03:38:36.936+0000] {taskinstance.py:1382} INFO - Executing <Task(PythonOperator): merge_locations_with_currencies> on 2023-11-04 03:31:06.668121+00:00
[2023-11-04T03:38:36.942+0000] {standard_task_runner.py:57} INFO - Started process 43840 to run task
[2023-11-04T03:38:36.942+0000] {clientserver.py:543} INFO - Closing down clientserver connection
[2023-11-04T03:38:36.945+0000] {standard_task_runner.py:84} INFO - Running: ['***', 'tasks', 'run', 'col_api_etl', 'merge_locations_with_currencies', 'manual__2023-11-04T03:31:06.668121+00:00', '--job-id', '1313', '--raw', '--subdir', 'DAGS_FOLDER/col_api_etl.py', '--cfg-path', '/tmp/tmpeichez47']
[2023-11-04T03:38:36.947+0000] {standard_task_runner.py:85} INFO - Job 1313: Subtask merge_locations_with_currencies
[2023-11-04T03:38:36.984+0000] {logging_mixin.py:151} INFO - Changing /opt/***/logs/dag_id=col_api_etl/run_id=manual__2023-11-04T03:31:06.668121+00:00/task_id=merge_locations_with_currencies permission to 509
[2023-11-04T03:38:36.985+0000] {logging_mixin.py:151} INFO - Failed to change /opt/***/logs/dag_id=col_api_etl/run_id=manual__2023-11-04T03:31:06.668121+00:00/task_id=merge_locations_with_currencies permission to 509: [Errno 1] Operation not permitted: '/opt/***/logs/dag_id=col_api_etl/run_id=manual__2023-11-04T03:31:06.668121+00:00/task_id=merge_locations_with_currencies'
[2023-11-04T03:38:36.986+0000] {task_command.py:415} INFO - Running <TaskInstance: col_api_etl.merge_locations_with_currencies manual__2023-11-04T03:31:06.668121+00:00 [running]> on host 0bcf85c4b011
[2023-11-04T03:38:37.210+0000] {taskinstance.py:1660} INFO - Exporting env vars: AIRFLOW_CTX_DAG_OWNER='***' AIRFLOW_CTX_DAG_ID='col_api_etl' AIRFLOW_CTX_TASK_ID='merge_locations_with_currencies' AIRFLOW_CTX_EXECUTION_DATE='2023-11-04T03:31:06.668121+00:00' AIRFLOW_CTX_TRY_NUMBER='1' AIRFLOW_CTX_DAG_RUN_ID='manual__2023-11-04T03:31:06.668121+00:00'
[2023-11-04T03:38:37.628+0000] {clientserver.py:505} INFO - Error while sending or receiving.
Traceback (most recent call last):
  File "/home/airflow/.local/lib/python3.8/site-packages/py4j/clientserver.py", line 503, in send_command
    self.socket.sendall(command.encode("utf-8"))
ConnectionResetError: [Errno 104] Connection reset by peer
[2023-11-04T03:38:37.629+0000] {clientserver.py:543} INFO - Closing down clientserver connection
[2023-11-04T03:38:37.630+0000] {java_gateway.py:1052} INFO - Exception while sending command.
Traceback (most recent call last):
  File "/home/airflow/.local/lib/python3.8/site-packages/py4j/clientserver.py", line 503, in send_command
    self.socket.sendall(command.encode("utf-8"))
ConnectionResetError: [Errno 104] Connection reset by peer

During handling of the above exception, another exception occurred:

Traceback (most recent call last):
  File "/home/airflow/.local/lib/python3.8/site-packages/py4j/java_gateway.py", line 1038, in send_command
    response = connection.send_command(command)
  File "/home/airflow/.local/lib/python3.8/site-packages/py4j/clientserver.py", line 506, in send_command
    raise Py4JNetworkError(
py4j.protocol.Py4JNetworkError: Error while sending
[2023-11-04T03:38:37.632+0000] {clientserver.py:543} INFO - Closing down clientserver connection
[2023-11-04T03:38:46.362+0000] {python.py:194} INFO - Done. Returned value was: None
[2023-11-04T03:38:46.372+0000] {taskinstance.py:1400} INFO - Marking task as SUCCESS. dag_id=col_api_etl, task_id=merge_locations_with_currencies, execution_date=20231104T033106, start_date=20231104T033836, end_date=20231104T033846
[2023-11-04T03:38:46.421+0000] {local_task_job_runner.py:228} INFO - Task exited with return code 0
