[2023-11-25T08:08:27.779+0000] {taskinstance.py:1159} INFO - Dependencies all met for dep_context=non-requeueable deps ti=<TaskInstance: col_api_etl.extract_livingcost_prices_from_city manual__2023-11-25T08:08:09.703587+00:00 [queued]>
[2023-11-25T08:08:27.813+0000] {taskinstance.py:1159} INFO - Dependencies all met for dep_context=requeueable deps ti=<TaskInstance: col_api_etl.extract_livingcost_prices_from_city manual__2023-11-25T08:08:09.703587+00:00 [queued]>
[2023-11-25T08:08:27.813+0000] {taskinstance.py:1361} INFO - Starting attempt 1 of 2
[2023-11-25T08:08:27.834+0000] {taskinstance.py:1382} INFO - Executing <Task(PythonOperator): extract_livingcost_prices_from_city> on 2023-11-25 08:08:09.703587+00:00
[2023-11-25T08:08:27.842+0000] {standard_task_runner.py:57} INFO - Started process 2160 to run task
[2023-11-25T08:08:27.846+0000] {clientserver.py:543} INFO - Closing down clientserver connection
[2023-11-25T08:08:27.854+0000] {standard_task_runner.py:84} INFO - Running: ['***', 'tasks', 'run', 'col_api_etl', 'extract_livingcost_prices_from_city', 'manual__2023-11-25T08:08:09.703587+00:00', '--job-id', '20', '--raw', '--subdir', 'DAGS_FOLDER/col_api_etl.py', '--cfg-path', '/tmp/tmpnovtstay']
[2023-11-25T08:08:27.858+0000] {standard_task_runner.py:85} INFO - Job 20: Subtask extract_livingcost_prices_from_city
[2023-11-25T08:08:27.991+0000] {task_command.py:415} INFO - Running <TaskInstance: col_api_etl.extract_livingcost_prices_from_city manual__2023-11-25T08:08:09.703587+00:00 [running]> on host 9b6b24afef42
[2023-11-25T08:08:28.064+0000] {clientserver.py:505} INFO - Error while sending or receiving.
Traceback (most recent call last):
  File "/home/airflow/.local/lib/python3.8/site-packages/py4j/clientserver.py", line 503, in send_command
    self.socket.sendall(command.encode("utf-8"))
ConnectionResetError: [Errno 104] Connection reset by peer
[2023-11-25T08:08:28.066+0000] {clientserver.py:543} INFO - Closing down clientserver connection
[2023-11-25T08:08:28.068+0000] {java_gateway.py:1052} INFO - Exception while sending command.
Traceback (most recent call last):
  File "/home/airflow/.local/lib/python3.8/site-packages/py4j/clientserver.py", line 503, in send_command
    self.socket.sendall(command.encode("utf-8"))
ConnectionResetError: [Errno 104] Connection reset by peer

During handling of the above exception, another exception occurred:

Traceback (most recent call last):
  File "/home/airflow/.local/lib/python3.8/site-packages/py4j/java_gateway.py", line 1038, in send_command
    response = connection.send_command(command)
  File "/home/airflow/.local/lib/python3.8/site-packages/py4j/clientserver.py", line 506, in send_command
    raise Py4JNetworkError(
py4j.protocol.Py4JNetworkError: Error while sending
[2023-11-25T08:08:28.090+0000] {clientserver.py:543} INFO - Closing down clientserver connection
[2023-11-25T08:08:28.924+0000] {taskinstance.py:1660} INFO - Exporting env vars: AIRFLOW_CTX_DAG_OWNER='***' AIRFLOW_CTX_DAG_ID='col_api_etl' AIRFLOW_CTX_TASK_ID='extract_livingcost_prices_from_city' AIRFLOW_CTX_EXECUTION_DATE='2023-11-25T08:08:09.703587+00:00' AIRFLOW_CTX_TRY_NUMBER='1' AIRFLOW_CTX_DAG_RUN_ID='manual__2023-11-25T08:08:09.703587+00:00'
[2023-11-25T08:08:29.652+0000] {logging_mixin.py:151} INFO - https://livingcost.org/cost/china/Hong-Kong
[2023-11-25T08:08:29.974+0000] {taskinstance.py:1943} ERROR - Task failed with exception
Traceback (most recent call last):
  File "/home/airflow/.local/lib/python3.8/site-packages/airflow/operators/python.py", line 192, in execute
    return_value = self.execute_callable()
  File "/home/airflow/.local/lib/python3.8/site-packages/airflow/operators/python.py", line 209, in execute_callable
    return self.python_callable(*self.op_args, **self.op_kwargs)
  File "/opt/airflow/dags/scripts/extraction.py", line 92, in extract_livingcost_prices_from_city
    eating_out_table = livingcost_city_page_html.find_all('table', {'class': 'table table-sm table-striped table-hover'})[0].find('tbody').find_all('tr')
IndexError: list index out of range
[2023-11-25T08:08:30.025+0000] {taskinstance.py:1400} INFO - Marking task as UP_FOR_RETRY. dag_id=col_api_etl, task_id=extract_livingcost_prices_from_city, execution_date=20231125T080809, start_date=20231125T080827, end_date=20231125T080830
[2023-11-25T08:08:30.043+0000] {standard_task_runner.py:104} ERROR - Failed to execute job 20 for task extract_livingcost_prices_from_city (list index out of range; 2160)
[2023-11-25T08:08:30.087+0000] {local_task_job_runner.py:228} INFO - Task exited with return code 1
