[2023-10-29T03:14:55.109+0000] {logging_mixin.py:151} INFO - Changing /opt/***/logs/dag_id=col_api_etl/run_id=manual__2023-10-29T03:14:43.287733+00:00/task_id=extract_numbeo_prices_from_city permission to 509
[2023-10-29T03:14:55.110+0000] {logging_mixin.py:151} INFO - Failed to change /opt/***/logs/dag_id=col_api_etl/run_id=manual__2023-10-29T03:14:43.287733+00:00/task_id=extract_numbeo_prices_from_city permission to 509: [Errno 1] Operation not permitted: '/opt/***/logs/dag_id=col_api_etl/run_id=manual__2023-10-29T03:14:43.287733+00:00/task_id=extract_numbeo_prices_from_city'
[2023-10-29T03:14:55.137+0000] {logging_mixin.py:151} INFO - Changing /opt/***/logs/dag_id=col_api_etl/run_id=manual__2023-10-29T03:14:43.287733+00:00/task_id=extract_numbeo_prices_from_city permission to 509
[2023-10-29T03:14:55.137+0000] {logging_mixin.py:151} INFO - Failed to change /opt/***/logs/dag_id=col_api_etl/run_id=manual__2023-10-29T03:14:43.287733+00:00/task_id=extract_numbeo_prices_from_city permission to 509: [Errno 1] Operation not permitted: '/opt/***/logs/dag_id=col_api_etl/run_id=manual__2023-10-29T03:14:43.287733+00:00/task_id=extract_numbeo_prices_from_city'
[2023-10-29T03:14:55.168+0000] {taskinstance.py:1159} INFO - Dependencies all met for dep_context=non-requeueable deps ti=<TaskInstance: col_api_etl.extract_numbeo_prices_from_city manual__2023-10-29T03:14:43.287733+00:00 [queued]>
[2023-10-29T03:14:55.178+0000] {taskinstance.py:1159} INFO - Dependencies all met for dep_context=requeueable deps ti=<TaskInstance: col_api_etl.extract_numbeo_prices_from_city manual__2023-10-29T03:14:43.287733+00:00 [queued]>
[2023-10-29T03:14:55.179+0000] {taskinstance.py:1361} INFO - Starting attempt 1 of 2
[2023-10-29T03:14:55.192+0000] {taskinstance.py:1382} INFO - Executing <Task(PythonOperator): extract_numbeo_prices_from_city> on 2023-10-29 03:14:43.287733+00:00
[2023-10-29T03:14:55.198+0000] {standard_task_runner.py:57} INFO - Started process 44283 to run task
[2023-10-29T03:14:55.198+0000] {clientserver.py:543} INFO - Closing down clientserver connection
[2023-10-29T03:14:55.202+0000] {standard_task_runner.py:84} INFO - Running: ['***', 'tasks', 'run', 'col_api_etl', 'extract_numbeo_prices_from_city', 'manual__2023-10-29T03:14:43.287733+00:00', '--job-id', '1110', '--raw', '--subdir', 'DAGS_FOLDER/col_api_etl.py', '--cfg-path', '/tmp/tmpyls_ds5e']
[2023-10-29T03:14:55.203+0000] {standard_task_runner.py:85} INFO - Job 1110: Subtask extract_numbeo_prices_from_city
[2023-10-29T03:14:55.240+0000] {logging_mixin.py:151} INFO - Changing /opt/***/logs/dag_id=col_api_etl/run_id=manual__2023-10-29T03:14:43.287733+00:00/task_id=extract_numbeo_prices_from_city permission to 509
[2023-10-29T03:14:55.240+0000] {logging_mixin.py:151} INFO - Failed to change /opt/***/logs/dag_id=col_api_etl/run_id=manual__2023-10-29T03:14:43.287733+00:00/task_id=extract_numbeo_prices_from_city permission to 509: [Errno 1] Operation not permitted: '/opt/***/logs/dag_id=col_api_etl/run_id=manual__2023-10-29T03:14:43.287733+00:00/task_id=extract_numbeo_prices_from_city'
[2023-10-29T03:14:55.242+0000] {task_command.py:415} INFO - Running <TaskInstance: col_api_etl.extract_numbeo_prices_from_city manual__2023-10-29T03:14:43.287733+00:00 [running]> on host ea85de3a6109
[2023-10-29T03:14:55.311+0000] {taskinstance.py:1660} INFO - Exporting env vars: AIRFLOW_CTX_DAG_OWNER='***' AIRFLOW_CTX_DAG_ID='col_api_etl' AIRFLOW_CTX_TASK_ID='extract_numbeo_prices_from_city' AIRFLOW_CTX_EXECUTION_DATE='2023-10-29T03:14:43.287733+00:00' AIRFLOW_CTX_TRY_NUMBER='1' AIRFLOW_CTX_DAG_RUN_ID='manual__2023-10-29T03:14:43.287733+00:00'
[2023-10-29T03:14:55.589+0000] {clientserver.py:505} INFO - Error while sending or receiving.
Traceback (most recent call last):
  File "/home/airflow/.local/lib/python3.8/site-packages/py4j/clientserver.py", line 503, in send_command
    self.socket.sendall(command.encode("utf-8"))
ConnectionResetError: [Errno 104] Connection reset by peer
[2023-10-29T03:14:55.591+0000] {clientserver.py:543} INFO - Closing down clientserver connection
[2023-10-29T03:14:55.591+0000] {java_gateway.py:1052} INFO - Exception while sending command.
Traceback (most recent call last):
  File "/home/airflow/.local/lib/python3.8/site-packages/py4j/clientserver.py", line 503, in send_command
    self.socket.sendall(command.encode("utf-8"))
ConnectionResetError: [Errno 104] Connection reset by peer

During handling of the above exception, another exception occurred:

Traceback (most recent call last):
  File "/home/airflow/.local/lib/python3.8/site-packages/py4j/java_gateway.py", line 1038, in send_command
    response = connection.send_command(command)
  File "/home/airflow/.local/lib/python3.8/site-packages/py4j/clientserver.py", line 506, in send_command
    raise Py4JNetworkError(
py4j.protocol.Py4JNetworkError: Error while sending
[2023-10-29T03:14:55.594+0000] {clientserver.py:543} INFO - Closing down clientserver connection
[2023-10-29T03:14:57.240+0000] {logging_mixin.py:151} INFO - Dubai
[2023-10-29T03:15:03.165+0000] {logging_mixin.py:151} INFO - Abu-Dhabi
[2023-10-29T03:15:08.860+0000] {logging_mixin.py:151} INFO - Sharjah
[2023-10-29T03:15:14.441+0000] {logging_mixin.py:151} INFO - Perth
[2023-10-29T03:15:20.047+0000] {logging_mixin.py:151} INFO - Melbourne
[2023-10-29T03:15:25.630+0000] {logging_mixin.py:151} INFO - Sydney
[2023-10-29T03:15:31.390+0000] {logging_mixin.py:151} INFO - Brisbane
[2023-10-29T03:15:36.921+0000] {logging_mixin.py:151} INFO - Hobart
[2023-10-29T03:15:42.148+0000] {logging_mixin.py:151} INFO - Adelaide
[2023-10-29T03:15:47.752+0000] {logging_mixin.py:151} INFO - Canberra
[2023-10-29T03:15:53.272+0000] {logging_mixin.py:151} INFO - Darwin
[2023-10-29T03:15:58.531+0000] {logging_mixin.py:151} INFO - Sarajevo
[2023-10-29T03:16:04.128+0000] {logging_mixin.py:151} INFO - Manama
[2023-10-29T03:16:09.639+0000] {logging_mixin.py:151} INFO - Sofia
[2023-10-29T03:16:15.560+0000] {logging_mixin.py:151} INFO - Sao-Paulo
[2023-10-29T03:16:21.276+0000] {logging_mixin.py:151} INFO - Rio-De-Janeiro
[2023-10-29T03:16:26.913+0000] {logging_mixin.py:151} INFO - Brasilia
[2023-10-29T03:16:32.541+0000] {logging_mixin.py:151} INFO - Toronto
[2023-10-29T03:16:38.599+0000] {logging_mixin.py:151} INFO - Montreal
[2023-10-29T03:16:44.548+0000] {logging_mixin.py:151} INFO - Vancouver
[2023-10-29T03:16:50.160+0000] {logging_mixin.py:151} INFO - Ottawa
[2023-10-29T03:16:55.742+0000] {logging_mixin.py:151} INFO - Calgary
[2023-10-29T03:17:01.359+0000] {logging_mixin.py:151} INFO - Edmonton
[2023-10-29T03:17:07.048+0000] {logging_mixin.py:151} INFO - Halifax
[2023-10-29T03:17:12.666+0000] {logging_mixin.py:151} INFO - Quebec-City
[2023-10-29T03:17:18.259+0000] {logging_mixin.py:151} INFO - Zurich
[2023-10-29T03:17:23.851+0000] {logging_mixin.py:151} INFO - Geneva
[2023-10-29T03:17:29.455+0000] {logging_mixin.py:151} INFO - Zug
[2023-10-29T03:17:34.779+0000] {logging_mixin.py:151} INFO - Basel
[2023-10-29T03:17:40.307+0000] {logging_mixin.py:151} INFO - Bern
[2023-10-29T03:17:45.580+0000] {logging_mixin.py:151} INFO - Lausanne
[2023-10-29T03:17:50.907+0000] {logging_mixin.py:151} INFO - Lugano
[2023-10-29T03:17:56.301+0000] {logging_mixin.py:151} INFO - Vaduz
[2023-10-29T03:18:01.608+0000] {logging_mixin.py:151} INFO - Santiago
[2023-10-29T03:18:07.236+0000] {logging_mixin.py:151} INFO - Chongqing
[2023-10-29T03:18:12.587+0000] {logging_mixin.py:151} INFO - Shanghai
[2023-10-29T03:18:18.126+0000] {logging_mixin.py:151} INFO - Beijing
[2023-10-29T03:18:23.945+0000] {logging_mixin.py:151} INFO - Chengdu
[2023-10-29T03:18:29.180+0000] {logging_mixin.py:151} INFO - Guangzhou
[2023-10-29T03:18:34.421+0000] {logging_mixin.py:151} INFO - Shenzhen
[2023-10-29T03:18:40.015+0000] {logging_mixin.py:151} INFO - Bogota
[2023-10-29T03:18:45.839+0000] {logging_mixin.py:151} INFO - Medellin
[2023-10-29T03:18:51.430+0000] {logging_mixin.py:151} INFO - Cali
[2023-10-29T03:18:56.954+0000] {logging_mixin.py:151} INFO - Cartagena
[2023-10-29T03:19:02.528+0000] {logging_mixin.py:151} INFO - San-Jose
[2023-10-29T03:19:07.784+0000] {logging_mixin.py:151} INFO - Prague
[2023-10-29T03:19:13.678+0000] {logging_mixin.py:151} INFO - Brno
[2023-10-29T03:19:19.298+0000] {logging_mixin.py:151} INFO - Ostrava
[2023-10-29T03:19:24.619+0000] {logging_mixin.py:151} INFO - Copenhagen
[2023-10-29T03:19:30.159+0000] {logging_mixin.py:151} INFO - Aarhus
[2023-10-29T03:19:35.996+0000] {logging_mixin.py:151} INFO - Aalborg
[2023-10-29T03:19:41.334+0000] {logging_mixin.py:151} INFO - Andorra-La-Vella
[2023-10-29T03:19:46.872+0000] {logging_mixin.py:151} INFO - Vienna
[2023-10-29T03:19:52.540+0000] {logging_mixin.py:151} INFO - Salzburg
[2023-10-29T03:19:58.480+0000] {logging_mixin.py:151} INFO - Graz
[2023-10-29T03:20:03.713+0000] {logging_mixin.py:151} INFO - Linz
[2023-10-29T03:20:09.024+0000] {logging_mixin.py:151} INFO - Innsbruck
[2023-10-29T03:20:14.563+0000] {logging_mixin.py:151} INFO - Brussels
[2023-10-29T03:20:20.239+0000] {logging_mixin.py:151} INFO - Antwerp
[2023-10-29T03:20:25.772+0000] {logging_mixin.py:151} INFO - Gent
[2023-10-29T03:20:31.452+0000] {logging_mixin.py:151} INFO - Liege
[2023-10-29T03:20:36.682+0000] {logging_mixin.py:151} INFO - Bruges
[2023-10-29T03:20:42.050+0000] {taskinstance.py:1943} ERROR - Task failed with exception
Traceback (most recent call last):
  File "/home/airflow/.local/lib/python3.8/site-packages/airflow/operators/python.py", line 192, in execute
    return_value = self.execute_callable()
  File "/home/airflow/.local/lib/python3.8/site-packages/airflow/operators/python.py", line 209, in execute_callable
    return self.python_callable(*self.op_args, **self.op_kwargs)
  File "/opt/airflow/dags/scripts/extraction.py", line 144, in extract_numbeo_prices_from_city
    prices_table = numbeo_prices_city_html.find('table', {'class': 'data_wide_table new_bar_table'}).find_all('tr')
AttributeError: 'NoneType' object has no attribute 'find_all'
[2023-10-29T03:20:42.063+0000] {taskinstance.py:1400} INFO - Marking task as UP_FOR_RETRY. dag_id=col_api_etl, task_id=extract_numbeo_prices_from_city, execution_date=20231029T031443, start_date=20231029T031455, end_date=20231029T032042
[2023-10-29T03:20:42.074+0000] {standard_task_runner.py:104} ERROR - Failed to execute job 1110 for task extract_numbeo_prices_from_city ('NoneType' object has no attribute 'find_all'; 44283)
[2023-10-29T03:20:42.116+0000] {local_task_job_runner.py:228} INFO - Task exited with return code 1
