[2023-11-01T00:37:56.880+0000] {logging_mixin.py:151} INFO - Changing /opt/***/logs/dag_id=col_api_etl/run_id=manual__2023-11-01T00:19:49.664511+00:00/task_id=extract_numbeo_prices_from_city permission to 509
[2023-11-01T00:37:56.881+0000] {logging_mixin.py:151} INFO - Failed to change /opt/***/logs/dag_id=col_api_etl/run_id=manual__2023-11-01T00:19:49.664511+00:00/task_id=extract_numbeo_prices_from_city permission to 509: [Errno 1] Operation not permitted: '/opt/***/logs/dag_id=col_api_etl/run_id=manual__2023-11-01T00:19:49.664511+00:00/task_id=extract_numbeo_prices_from_city'
[2023-11-01T00:37:56.936+0000] {logging_mixin.py:151} INFO - Changing /opt/***/logs/dag_id=col_api_etl/run_id=manual__2023-11-01T00:19:49.664511+00:00/task_id=extract_numbeo_prices_from_city permission to 509
[2023-11-01T00:37:56.937+0000] {logging_mixin.py:151} INFO - Failed to change /opt/***/logs/dag_id=col_api_etl/run_id=manual__2023-11-01T00:19:49.664511+00:00/task_id=extract_numbeo_prices_from_city permission to 509: [Errno 1] Operation not permitted: '/opt/***/logs/dag_id=col_api_etl/run_id=manual__2023-11-01T00:19:49.664511+00:00/task_id=extract_numbeo_prices_from_city'
[2023-11-01T00:37:56.993+0000] {taskinstance.py:1159} INFO - Dependencies all met for dep_context=non-requeueable deps ti=<TaskInstance: col_api_etl.extract_numbeo_prices_from_city manual__2023-11-01T00:19:49.664511+00:00 [queued]>
[2023-11-01T00:37:57.009+0000] {taskinstance.py:1159} INFO - Dependencies all met for dep_context=requeueable deps ti=<TaskInstance: col_api_etl.extract_numbeo_prices_from_city manual__2023-11-01T00:19:49.664511+00:00 [queued]>
[2023-11-01T00:37:57.010+0000] {taskinstance.py:1361} INFO - Starting attempt 2 of 2
[2023-11-01T00:37:57.034+0000] {taskinstance.py:1382} INFO - Executing <Task(PythonOperator): extract_numbeo_prices_from_city> on 2023-11-01 00:19:49.664511+00:00
[2023-11-01T00:37:57.042+0000] {standard_task_runner.py:57} INFO - Started process 13979 to run task
[2023-11-01T00:37:57.042+0000] {clientserver.py:543} INFO - Closing down clientserver connection
[2023-11-01T00:37:57.051+0000] {standard_task_runner.py:84} INFO - Running: ['***', 'tasks', 'run', 'col_api_etl', 'extract_numbeo_prices_from_city', 'manual__2023-11-01T00:19:49.664511+00:00', '--job-id', '1148', '--raw', '--subdir', 'DAGS_FOLDER/col_api_etl.py', '--cfg-path', '/tmp/tmpyvsvv706']
[2023-11-01T00:37:57.061+0000] {standard_task_runner.py:85} INFO - Job 1148: Subtask extract_numbeo_prices_from_city
[2023-11-01T00:37:57.174+0000] {logging_mixin.py:151} INFO - Changing /opt/***/logs/dag_id=col_api_etl/run_id=manual__2023-11-01T00:19:49.664511+00:00/task_id=extract_numbeo_prices_from_city permission to 509
[2023-11-01T00:37:57.175+0000] {logging_mixin.py:151} INFO - Failed to change /opt/***/logs/dag_id=col_api_etl/run_id=manual__2023-11-01T00:19:49.664511+00:00/task_id=extract_numbeo_prices_from_city permission to 509: [Errno 1] Operation not permitted: '/opt/***/logs/dag_id=col_api_etl/run_id=manual__2023-11-01T00:19:49.664511+00:00/task_id=extract_numbeo_prices_from_city'
[2023-11-01T00:37:57.180+0000] {task_command.py:415} INFO - Running <TaskInstance: col_api_etl.extract_numbeo_prices_from_city manual__2023-11-01T00:19:49.664511+00:00 [running]> on host 65ec58942685
[2023-11-01T00:37:57.782+0000] {taskinstance.py:1660} INFO - Exporting env vars: AIRFLOW_CTX_DAG_OWNER='***' AIRFLOW_CTX_DAG_ID='col_api_etl' AIRFLOW_CTX_TASK_ID='extract_numbeo_prices_from_city' AIRFLOW_CTX_EXECUTION_DATE='2023-11-01T00:19:49.664511+00:00' AIRFLOW_CTX_TRY_NUMBER='2' AIRFLOW_CTX_DAG_RUN_ID='manual__2023-11-01T00:19:49.664511+00:00'
[2023-11-01T00:37:59.256+0000] {logging_mixin.py:151} INFO - Dubai
[2023-11-01T00:38:05.540+0000] {logging_mixin.py:151} INFO - Abu-Dhabi
[2023-11-01T00:38:11.520+0000] {logging_mixin.py:151} INFO - Sharjah
[2023-11-01T00:38:17.217+0000] {logging_mixin.py:151} INFO - Perth
[2023-11-01T00:38:23.003+0000] {logging_mixin.py:151} INFO - Melbourne
[2023-11-01T00:38:28.760+0000] {logging_mixin.py:151} INFO - Sydney
[2023-11-01T00:38:34.654+0000] {logging_mixin.py:151} INFO - Brisbane
[2023-11-01T00:38:40.312+0000] {logging_mixin.py:151} INFO - Hobart
[2023-11-01T00:38:50.328+0000] {taskinstance.py:1943} ERROR - Task failed with exception
Traceback (most recent call last):
  File "/home/airflow/.local/lib/python3.8/site-packages/urllib3/connection.py", line 174, in _new_conn
    conn = connection.create_connection(
  File "/home/airflow/.local/lib/python3.8/site-packages/urllib3/util/connection.py", line 72, in create_connection
    for res in socket.getaddrinfo(host, port, family, socket.SOCK_STREAM):
  File "/usr/local/lib/python3.8/socket.py", line 918, in getaddrinfo
    for res in _socket.getaddrinfo(host, port, family, type, proto, flags):
socket.gaierror: [Errno -3] Temporary failure in name resolution

During handling of the above exception, another exception occurred:

Traceback (most recent call last):
  File "/home/airflow/.local/lib/python3.8/site-packages/urllib3/connectionpool.py", line 714, in urlopen
    httplib_response = self._make_request(
  File "/home/airflow/.local/lib/python3.8/site-packages/urllib3/connectionpool.py", line 403, in _make_request
    self._validate_conn(conn)
  File "/home/airflow/.local/lib/python3.8/site-packages/urllib3/connectionpool.py", line 1053, in _validate_conn
    conn.connect()
  File "/home/airflow/.local/lib/python3.8/site-packages/urllib3/connection.py", line 363, in connect
    self.sock = conn = self._new_conn()
  File "/home/airflow/.local/lib/python3.8/site-packages/urllib3/connection.py", line 186, in _new_conn
    raise NewConnectionError(
urllib3.exceptions.NewConnectionError: <urllib3.connection.HTTPSConnection object at 0x7fc495a3f1f0>: Failed to establish a new connection: [Errno -3] Temporary failure in name resolution

During handling of the above exception, another exception occurred:

Traceback (most recent call last):
  File "/home/airflow/.local/lib/python3.8/site-packages/requests/adapters.py", line 486, in send
    resp = conn.urlopen(
  File "/home/airflow/.local/lib/python3.8/site-packages/urllib3/connectionpool.py", line 798, in urlopen
    retries = retries.increment(
  File "/home/airflow/.local/lib/python3.8/site-packages/urllib3/util/retry.py", line 592, in increment
    raise MaxRetryError(_pool, url, error or ResponseError(cause))
urllib3.exceptions.MaxRetryError: HTTPSConnectionPool(host='www.numbeo.com', port=443): Max retries exceeded with url: /cost-of-living/in/Hobart?displayCurrency=USD (Caused by NewConnectionError('<urllib3.connection.HTTPSConnection object at 0x7fc495a3f1f0>: Failed to establish a new connection: [Errno -3] Temporary failure in name resolution'))

During handling of the above exception, another exception occurred:

Traceback (most recent call last):
  File "/home/airflow/.local/lib/python3.8/site-packages/airflow/operators/python.py", line 192, in execute
    return_value = self.execute_callable()
  File "/home/airflow/.local/lib/python3.8/site-packages/airflow/operators/python.py", line 209, in execute_callable
    return self.python_callable(*self.op_args, **self.op_kwargs)
  File "/opt/airflow/dags/scripts/extraction.py", line 154, in extract_numbeo_prices_from_city
    response = requests.get(f'https://www.numbeo.com/cost-of-living/in/{formatted_city_name}?displayCurrency=USD')
  File "/home/airflow/.local/lib/python3.8/site-packages/requests/api.py", line 73, in get
    return request("get", url, params=params, **kwargs)
  File "/home/airflow/.local/lib/python3.8/site-packages/requests/api.py", line 59, in request
    return session.request(method=method, url=url, **kwargs)
  File "/home/airflow/.local/lib/python3.8/site-packages/requests/sessions.py", line 589, in request
    resp = self.send(prep, **send_kwargs)
  File "/home/airflow/.local/lib/python3.8/site-packages/requests/sessions.py", line 703, in send
    r = adapter.send(request, **kwargs)
  File "/home/airflow/.local/lib/python3.8/site-packages/requests/adapters.py", line 519, in send
    raise ConnectionError(e, request=request)
requests.exceptions.ConnectionError: HTTPSConnectionPool(host='www.numbeo.com', port=443): Max retries exceeded with url: /cost-of-living/in/Hobart?displayCurrency=USD (Caused by NewConnectionError('<urllib3.connection.HTTPSConnection object at 0x7fc495a3f1f0>: Failed to establish a new connection: [Errno -3] Temporary failure in name resolution'))
[2023-11-01T00:38:50.362+0000] {taskinstance.py:1400} INFO - Marking task as FAILED. dag_id=col_api_etl, task_id=extract_numbeo_prices_from_city, execution_date=20231101T001949, start_date=20231101T003756, end_date=20231101T003850
[2023-11-01T00:38:50.386+0000] {standard_task_runner.py:104} ERROR - Failed to execute job 1148 for task extract_numbeo_prices_from_city (HTTPSConnectionPool(host='www.numbeo.com', port=443): Max retries exceeded with url: /cost-of-living/in/Hobart?displayCurrency=USD (Caused by NewConnectionError('<urllib3.connection.HTTPSConnection object at 0x7fc495a3f1f0>: Failed to establish a new connection: [Errno -3] Temporary failure in name resolution')); 13979)
[2023-11-01T00:38:50.438+0000] {local_task_job_runner.py:228} INFO - Task exited with return code 1
