[2023-11-25T08:18:51.895+0000] {taskinstance.py:1159} INFO - Dependencies all met for dep_context=non-requeueable deps ti=<TaskInstance: col_api_etl.extract_livingcost_prices_from_city manual__2023-11-25T08:18:34.841040+00:00 [queued]>
[2023-11-25T08:18:51.905+0000] {taskinstance.py:1159} INFO - Dependencies all met for dep_context=requeueable deps ti=<TaskInstance: col_api_etl.extract_livingcost_prices_from_city manual__2023-11-25T08:18:34.841040+00:00 [queued]>
[2023-11-25T08:18:51.905+0000] {taskinstance.py:1361} INFO - Starting attempt 1 of 2
[2023-11-25T08:18:51.923+0000] {taskinstance.py:1382} INFO - Executing <Task(PythonOperator): extract_livingcost_prices_from_city> on 2023-11-25 08:18:34.841040+00:00
[2023-11-25T08:18:51.930+0000] {standard_task_runner.py:57} INFO - Started process 4630 to run task
[2023-11-25T08:18:51.934+0000] {clientserver.py:543} INFO - Closing down clientserver connection
[2023-11-25T08:18:51.938+0000] {standard_task_runner.py:84} INFO - Running: ['***', 'tasks', 'run', 'col_api_etl', 'extract_livingcost_prices_from_city', 'manual__2023-11-25T08:18:34.841040+00:00', '--job-id', '25', '--raw', '--subdir', 'DAGS_FOLDER/col_api_etl.py', '--cfg-path', '/tmp/tmps71mh3an']
[2023-11-25T08:18:51.941+0000] {standard_task_runner.py:85} INFO - Job 25: Subtask extract_livingcost_prices_from_city
[2023-11-25T08:18:51.995+0000] {clientserver.py:505} INFO - Error while sending or receiving.
Traceback (most recent call last):
  File "/home/airflow/.local/lib/python3.8/site-packages/py4j/clientserver.py", line 503, in send_command
    self.socket.sendall(command.encode("utf-8"))
ConnectionResetError: [Errno 104] Connection reset by peer
[2023-11-25T08:18:51.997+0000] {clientserver.py:543} INFO - Closing down clientserver connection
[2023-11-25T08:18:51.997+0000] {java_gateway.py:1052} INFO - Exception while sending command.
Traceback (most recent call last):
  File "/home/airflow/.local/lib/python3.8/site-packages/py4j/clientserver.py", line 503, in send_command
    self.socket.sendall(command.encode("utf-8"))
ConnectionResetError: [Errno 104] Connection reset by peer

During handling of the above exception, another exception occurred:

Traceback (most recent call last):
  File "/home/airflow/.local/lib/python3.8/site-packages/py4j/java_gateway.py", line 1038, in send_command
    response = connection.send_command(command)
  File "/home/airflow/.local/lib/python3.8/site-packages/py4j/clientserver.py", line 506, in send_command
    raise Py4JNetworkError(
py4j.protocol.Py4JNetworkError: Error while sending
[2023-11-25T08:18:52.011+0000] {clientserver.py:543} INFO - Closing down clientserver connection
[2023-11-25T08:18:52.023+0000] {task_command.py:415} INFO - Running <TaskInstance: col_api_etl.extract_livingcost_prices_from_city manual__2023-11-25T08:18:34.841040+00:00 [running]> on host 9b6b24afef42
[2023-11-25T08:18:52.344+0000] {taskinstance.py:1660} INFO - Exporting env vars: AIRFLOW_CTX_DAG_OWNER='***' AIRFLOW_CTX_DAG_ID='col_api_etl' AIRFLOW_CTX_TASK_ID='extract_livingcost_prices_from_city' AIRFLOW_CTX_EXECUTION_DATE='2023-11-25T08:18:34.841040+00:00' AIRFLOW_CTX_TRY_NUMBER='1' AIRFLOW_CTX_DAG_RUN_ID='manual__2023-11-25T08:18:34.841040+00:00'
[2023-11-25T08:18:52.675+0000] {python.py:194} INFO - Done. Returned value was: None
[2023-11-25T08:18:52.692+0000] {taskinstance.py:1400} INFO - Marking task as SUCCESS. dag_id=col_api_etl, task_id=extract_livingcost_prices_from_city, execution_date=20231125T081834, start_date=20231125T081851, end_date=20231125T081852
[2023-11-25T08:18:52.754+0000] {local_task_job_runner.py:228} INFO - Task exited with return code 0
