[2023-10-29T01:07:34.795+0000] {logging_mixin.py:151} INFO - Changing /opt/***/logs/dag_id=col_api_etl/run_id=manual__2023-10-29T01:05:58.103122+00:00/task_id=extract_numbeo_prices_from_city permission to 509
[2023-10-29T01:07:34.795+0000] {logging_mixin.py:151} INFO - Failed to change /opt/***/logs/dag_id=col_api_etl/run_id=manual__2023-10-29T01:05:58.103122+00:00/task_id=extract_numbeo_prices_from_city permission to 509: [Errno 1] Operation not permitted: '/opt/***/logs/dag_id=col_api_etl/run_id=manual__2023-10-29T01:05:58.103122+00:00/task_id=extract_numbeo_prices_from_city'
[2023-10-29T01:07:34.820+0000] {logging_mixin.py:151} INFO - Changing /opt/***/logs/dag_id=col_api_etl/run_id=manual__2023-10-29T01:05:58.103122+00:00/task_id=extract_numbeo_prices_from_city permission to 509
[2023-10-29T01:07:34.821+0000] {logging_mixin.py:151} INFO - Failed to change /opt/***/logs/dag_id=col_api_etl/run_id=manual__2023-10-29T01:05:58.103122+00:00/task_id=extract_numbeo_prices_from_city permission to 509: [Errno 1] Operation not permitted: '/opt/***/logs/dag_id=col_api_etl/run_id=manual__2023-10-29T01:05:58.103122+00:00/task_id=extract_numbeo_prices_from_city'
[2023-10-29T01:07:34.851+0000] {taskinstance.py:1159} INFO - Dependencies all met for dep_context=non-requeueable deps ti=<TaskInstance: col_api_etl.extract_numbeo_prices_from_city manual__2023-10-29T01:05:58.103122+00:00 [queued]>
[2023-10-29T01:07:34.860+0000] {taskinstance.py:1159} INFO - Dependencies all met for dep_context=requeueable deps ti=<TaskInstance: col_api_etl.extract_numbeo_prices_from_city manual__2023-10-29T01:05:58.103122+00:00 [queued]>
[2023-10-29T01:07:34.860+0000] {taskinstance.py:1361} INFO - Starting attempt 2 of 2
[2023-10-29T01:07:34.872+0000] {taskinstance.py:1382} INFO - Executing <Task(PythonOperator): extract_numbeo_prices_from_city> on 2023-10-29 01:05:58.103122+00:00
[2023-10-29T01:07:34.877+0000] {standard_task_runner.py:57} INFO - Started process 4902 to run task
[2023-10-29T01:07:34.877+0000] {clientserver.py:543} INFO - Closing down clientserver connection
[2023-10-29T01:07:34.880+0000] {standard_task_runner.py:84} INFO - Running: ['***', 'tasks', 'run', 'col_api_etl', 'extract_numbeo_prices_from_city', 'manual__2023-10-29T01:05:58.103122+00:00', '--job-id', '1093', '--raw', '--subdir', 'DAGS_FOLDER/col_api_etl.py', '--cfg-path', '/tmp/tmpjn8lnnsh']
[2023-10-29T01:07:34.882+0000] {standard_task_runner.py:85} INFO - Job 1093: Subtask extract_numbeo_prices_from_city
[2023-10-29T01:07:34.918+0000] {logging_mixin.py:151} INFO - Changing /opt/***/logs/dag_id=col_api_etl/run_id=manual__2023-10-29T01:05:58.103122+00:00/task_id=extract_numbeo_prices_from_city permission to 509
[2023-10-29T01:07:34.919+0000] {logging_mixin.py:151} INFO - Failed to change /opt/***/logs/dag_id=col_api_etl/run_id=manual__2023-10-29T01:05:58.103122+00:00/task_id=extract_numbeo_prices_from_city permission to 509: [Errno 1] Operation not permitted: '/opt/***/logs/dag_id=col_api_etl/run_id=manual__2023-10-29T01:05:58.103122+00:00/task_id=extract_numbeo_prices_from_city'
[2023-10-29T01:07:34.921+0000] {task_command.py:415} INFO - Running <TaskInstance: col_api_etl.extract_numbeo_prices_from_city manual__2023-10-29T01:05:58.103122+00:00 [running]> on host ea85de3a6109
[2023-10-29T01:07:34.989+0000] {taskinstance.py:1660} INFO - Exporting env vars: AIRFLOW_CTX_DAG_OWNER='***' AIRFLOW_CTX_DAG_ID='col_api_etl' AIRFLOW_CTX_TASK_ID='extract_numbeo_prices_from_city' AIRFLOW_CTX_EXECUTION_DATE='2023-10-29T01:05:58.103122+00:00' AIRFLOW_CTX_TRY_NUMBER='2' AIRFLOW_CTX_DAG_RUN_ID='manual__2023-10-29T01:05:58.103122+00:00'
[2023-10-29T01:07:36.534+0000] {logging_mixin.py:151} INFO - Dubai
[2023-10-29T01:07:38.203+0000] {logging_mixin.py:151} INFO - Abu-Dhabi
[2023-10-29T01:07:39.859+0000] {logging_mixin.py:151} INFO - Sharjah
[2023-10-29T01:07:41.050+0000] {logging_mixin.py:151} INFO - Perth
[2023-10-29T01:07:42.530+0000] {logging_mixin.py:151} INFO - Melbourne
[2023-10-29T01:07:44.134+0000] {logging_mixin.py:151} INFO - Sydney
[2023-10-29T01:07:45.993+0000] {logging_mixin.py:151} INFO - Brisbane
[2023-10-29T01:07:47.735+0000] {logging_mixin.py:151} INFO - Hobart
[2023-10-29T01:07:49.000+0000] {logging_mixin.py:151} INFO - Adelaide
[2023-10-29T01:07:50.519+0000] {logging_mixin.py:151} INFO - Canberra
[2023-10-29T01:07:51.730+0000] {logging_mixin.py:151} INFO - Darwin
[2023-10-29T01:07:53.163+0000] {logging_mixin.py:151} INFO - Sarajevo
[2023-10-29T01:07:54.702+0000] {logging_mixin.py:151} INFO - Manama
[2023-10-29T01:07:56.344+0000] {logging_mixin.py:151} INFO - Sofia
[2023-10-29T01:07:57.920+0000] {logging_mixin.py:151} INFO - Sao-Paulo
[2023-10-29T01:07:59.781+0000] {logging_mixin.py:151} INFO - Rio-De-Janeiro
[2023-10-29T01:08:01.422+0000] {logging_mixin.py:151} INFO - Brasilia
[2023-10-29T01:08:03.090+0000] {logging_mixin.py:151} INFO - Toronto
[2023-10-29T01:08:04.741+0000] {logging_mixin.py:151} INFO - Montreal
[2023-10-29T01:08:06.282+0000] {logging_mixin.py:151} INFO - Vancouver
[2023-10-29T01:08:07.924+0000] {logging_mixin.py:151} INFO - Ottawa
[2023-10-29T01:08:09.547+0000] {logging_mixin.py:151} INFO - Calgary
[2023-10-29T01:08:11.174+0000] {logging_mixin.py:151} INFO - Edmonton
[2023-10-29T01:08:12.875+0000] {logging_mixin.py:151} INFO - Halifax
[2023-10-29T01:08:14.401+0000] {logging_mixin.py:151} INFO - Quebec-City
[2023-10-29T01:08:15.925+0000] {logging_mixin.py:151} INFO - Zurich
[2023-10-29T01:08:17.449+0000] {logging_mixin.py:151} INFO - Geneva
[2023-10-29T01:08:19.253+0000] {logging_mixin.py:151} INFO - Zug
[2023-10-29T01:08:20.719+0000] {logging_mixin.py:151} INFO - Basel
[2023-10-29T01:08:22.454+0000] {logging_mixin.py:151} INFO - Bern
[2023-10-29T01:08:24.303+0000] {logging_mixin.py:151} INFO - Lausanne
[2023-10-29T01:08:26.139+0000] {logging_mixin.py:151} INFO - Ticino
[2023-10-29T01:08:29.007+0000] {taskinstance.py:1943} ERROR - Task failed with exception
Traceback (most recent call last):
  File "/home/airflow/.local/lib/python3.8/site-packages/airflow/operators/python.py", line 192, in execute
    return_value = self.execute_callable()
  File "/home/airflow/.local/lib/python3.8/site-packages/airflow/operators/python.py", line 209, in execute_callable
    return self.python_callable(*self.op_args, **self.op_kwargs)
  File "/opt/airflow/dags/scripts/extraction.py", line 135, in extract_numbeo_prices_from_city
    prices_table = numbeo_prices_city_html.find('table', {'class': 'data_wide_table new_bar_table'}).find_all('tr')
AttributeError: 'NoneType' object has no attribute 'find_all'
[2023-10-29T01:08:29.021+0000] {taskinstance.py:1400} INFO - Marking task as FAILED. dag_id=col_api_etl, task_id=extract_numbeo_prices_from_city, execution_date=20231029T010558, start_date=20231029T010734, end_date=20231029T010829
[2023-10-29T01:08:29.032+0000] {standard_task_runner.py:104} ERROR - Failed to execute job 1093 for task extract_numbeo_prices_from_city ('NoneType' object has no attribute 'find_all'; 4902)
[2023-10-29T01:08:29.055+0000] {local_task_job_runner.py:228} INFO - Task exited with return code 1
