[2023-11-25T10:30:33.707+0000] {taskinstance.py:1159} INFO - Dependencies all met for dep_context=non-requeueable deps ti=<TaskInstance: col_api_etl.extract_livingcost_prices_from_city manual__2023-11-25T10:30:17.600607+00:00 [queued]>
[2023-11-25T10:30:33.716+0000] {taskinstance.py:1159} INFO - Dependencies all met for dep_context=requeueable deps ti=<TaskInstance: col_api_etl.extract_livingcost_prices_from_city manual__2023-11-25T10:30:17.600607+00:00 [queued]>
[2023-11-25T10:30:33.717+0000] {taskinstance.py:1361} INFO - Starting attempt 1 of 2
[2023-11-25T10:30:33.736+0000] {taskinstance.py:1382} INFO - Executing <Task(PythonOperator): extract_livingcost_prices_from_city> on 2023-11-25 10:30:17.600607+00:00
[2023-11-25T10:30:33.742+0000] {standard_task_runner.py:57} INFO - Started process 11325 to run task
[2023-11-25T10:30:33.746+0000] {clientserver.py:543} INFO - Closing down clientserver connection
[2023-11-25T10:30:33.757+0000] {standard_task_runner.py:84} INFO - Running: ['***', 'tasks', 'run', 'col_api_etl', 'extract_livingcost_prices_from_city', 'manual__2023-11-25T10:30:17.600607+00:00', '--job-id', '69', '--raw', '--subdir', 'DAGS_FOLDER/col_api_etl.py', '--cfg-path', '/tmp/tmpljubsjh4']
[2023-11-25T10:30:33.759+0000] {standard_task_runner.py:85} INFO - Job 69: Subtask extract_livingcost_prices_from_city
[2023-11-25T10:30:33.832+0000] {task_command.py:415} INFO - Running <TaskInstance: col_api_etl.extract_livingcost_prices_from_city manual__2023-11-25T10:30:17.600607+00:00 [running]> on host 9b6b24afef42
[2023-11-25T10:30:33.959+0000] {taskinstance.py:1660} INFO - Exporting env vars: AIRFLOW_CTX_DAG_OWNER='***' AIRFLOW_CTX_DAG_ID='col_api_etl' AIRFLOW_CTX_TASK_ID='extract_livingcost_prices_from_city' AIRFLOW_CTX_EXECUTION_DATE='2023-11-25T10:30:17.600607+00:00' AIRFLOW_CTX_TRY_NUMBER='1' AIRFLOW_CTX_DAG_RUN_ID='manual__2023-11-25T10:30:17.600607+00:00'
[2023-11-25T10:30:34.070+0000] {clientserver.py:505} INFO - Error while sending or receiving.
Traceback (most recent call last):
  File "/home/airflow/.local/lib/python3.8/site-packages/py4j/clientserver.py", line 503, in send_command
    self.socket.sendall(command.encode("utf-8"))
ConnectionResetError: [Errno 104] Connection reset by peer
[2023-11-25T10:30:34.072+0000] {clientserver.py:543} INFO - Closing down clientserver connection
[2023-11-25T10:30:34.072+0000] {java_gateway.py:1052} INFO - Exception while sending command.
Traceback (most recent call last):
  File "/home/airflow/.local/lib/python3.8/site-packages/py4j/clientserver.py", line 503, in send_command
    self.socket.sendall(command.encode("utf-8"))
ConnectionResetError: [Errno 104] Connection reset by peer

During handling of the above exception, another exception occurred:

Traceback (most recent call last):
  File "/home/airflow/.local/lib/python3.8/site-packages/py4j/java_gateway.py", line 1038, in send_command
    response = connection.send_command(command)
  File "/home/airflow/.local/lib/python3.8/site-packages/py4j/clientserver.py", line 506, in send_command
    raise Py4JNetworkError(
py4j.protocol.Py4JNetworkError: Error while sending
[2023-11-25T10:30:34.085+0000] {clientserver.py:543} INFO - Closing down clientserver connection
[2023-11-25T10:33:32.035+0000] {taskinstance.py:1943} ERROR - Task failed with exception
Traceback (most recent call last):
  File "/home/airflow/.local/lib/python3.8/site-packages/urllib3/connection.py", line 174, in _new_conn
    conn = connection.create_connection(
  File "/home/airflow/.local/lib/python3.8/site-packages/urllib3/util/connection.py", line 72, in create_connection
    for res in socket.getaddrinfo(host, port, family, socket.SOCK_STREAM):
  File "/usr/local/lib/python3.8/socket.py", line 918, in getaddrinfo
    for res in _socket.getaddrinfo(host, port, family, type, proto, flags):
socket.gaierror: [Errno -3] Temporary failure in name resolution

During handling of the above exception, another exception occurred:

Traceback (most recent call last):
  File "/home/airflow/.local/lib/python3.8/site-packages/urllib3/connectionpool.py", line 714, in urlopen
    httplib_response = self._make_request(
  File "/home/airflow/.local/lib/python3.8/site-packages/urllib3/connectionpool.py", line 403, in _make_request
    self._validate_conn(conn)
  File "/home/airflow/.local/lib/python3.8/site-packages/urllib3/connectionpool.py", line 1053, in _validate_conn
    conn.connect()
  File "/home/airflow/.local/lib/python3.8/site-packages/urllib3/connection.py", line 363, in connect
    self.sock = conn = self._new_conn()
  File "/home/airflow/.local/lib/python3.8/site-packages/urllib3/connection.py", line 186, in _new_conn
    raise NewConnectionError(
urllib3.exceptions.NewConnectionError: <urllib3.connection.HTTPSConnection object at 0x7f056a657d60>: Failed to establish a new connection: [Errno -3] Temporary failure in name resolution

During handling of the above exception, another exception occurred:

Traceback (most recent call last):
  File "/home/airflow/.local/lib/python3.8/site-packages/requests/adapters.py", line 486, in send
    resp = conn.urlopen(
  File "/home/airflow/.local/lib/python3.8/site-packages/urllib3/connectionpool.py", line 798, in urlopen
    retries = retries.increment(
  File "/home/airflow/.local/lib/python3.8/site-packages/urllib3/util/retry.py", line 592, in increment
    raise MaxRetryError(_pool, url, error or ResponseError(cause))
urllib3.exceptions.MaxRetryError: HTTPSConnectionPool(host='livingcost.org', port=443): Max retries exceeded with url: /cost/saudi-arabia/riyadh (Caused by NewConnectionError('<urllib3.connection.HTTPSConnection object at 0x7f056a657d60>: Failed to establish a new connection: [Errno -3] Temporary failure in name resolution'))

During handling of the above exception, another exception occurred:

Traceback (most recent call last):
  File "/home/airflow/.local/lib/python3.8/site-packages/airflow/operators/python.py", line 192, in execute
    return_value = self.execute_callable()
  File "/home/airflow/.local/lib/python3.8/site-packages/airflow/operators/python.py", line 209, in execute_callable
    return self.python_callable(*self.op_args, **self.op_kwargs)
  File "/opt/airflow/dags/scripts/extraction.py", line 86, in extract_livingcost_prices_from_city
    response = requests.get(url_to_extract)
  File "/home/airflow/.local/lib/python3.8/site-packages/requests/api.py", line 73, in get
    return request("get", url, params=params, **kwargs)
  File "/home/airflow/.local/lib/python3.8/site-packages/requests/api.py", line 59, in request
    return session.request(method=method, url=url, **kwargs)
  File "/home/airflow/.local/lib/python3.8/site-packages/requests/sessions.py", line 589, in request
    resp = self.send(prep, **send_kwargs)
  File "/home/airflow/.local/lib/python3.8/site-packages/requests/sessions.py", line 703, in send
    r = adapter.send(request, **kwargs)
  File "/home/airflow/.local/lib/python3.8/site-packages/requests/adapters.py", line 519, in send
    raise ConnectionError(e, request=request)
requests.exceptions.ConnectionError: HTTPSConnectionPool(host='livingcost.org', port=443): Max retries exceeded with url: /cost/saudi-arabia/riyadh (Caused by NewConnectionError('<urllib3.connection.HTTPSConnection object at 0x7f056a657d60>: Failed to establish a new connection: [Errno -3] Temporary failure in name resolution'))
[2023-11-25T10:33:48.654+0000] {taskinstance.py:1400} INFO - Marking task as UP_FOR_RETRY. dag_id=col_api_etl, task_id=extract_livingcost_prices_from_city, execution_date=20231125T103017, start_date=20231125T103033, end_date=20231125T103348
[2023-11-25T10:33:48.725+0000] {standard_task_runner.py:104} ERROR - Failed to execute job 69 for task extract_livingcost_prices_from_city (HTTPSConnectionPool(host='livingcost.org', port=443): Max retries exceeded with url: /cost/saudi-arabia/riyadh (Caused by NewConnectionError('<urllib3.connection.HTTPSConnection object at 0x7f056a657d60>: Failed to establish a new connection: [Errno -3] Temporary failure in name resolution')); 11325)
[2023-11-25T10:33:48.760+0000] {local_task_job_runner.py:228} INFO - Task exited with return code 1
