[2023-11-01T23:53:25.134+0000] {logging_mixin.py:151} INFO - Changing /opt/***/logs/dag_id=col_api_etl/run_id=manual__2023-11-01T23:53:20.755582+00:00/task_id=extract_currency_conversion_rates permission to 509
[2023-11-01T23:53:25.135+0000] {logging_mixin.py:151} INFO - Failed to change /opt/***/logs/dag_id=col_api_etl/run_id=manual__2023-11-01T23:53:20.755582+00:00/task_id=extract_currency_conversion_rates permission to 509: [Errno 1] Operation not permitted: '/opt/***/logs/dag_id=col_api_etl/run_id=manual__2023-11-01T23:53:20.755582+00:00/task_id=extract_currency_conversion_rates'
[2023-11-01T23:53:25.167+0000] {logging_mixin.py:151} INFO - Changing /opt/***/logs/dag_id=col_api_etl/run_id=manual__2023-11-01T23:53:20.755582+00:00/task_id=extract_currency_conversion_rates permission to 509
[2023-11-01T23:53:25.168+0000] {logging_mixin.py:151} INFO - Failed to change /opt/***/logs/dag_id=col_api_etl/run_id=manual__2023-11-01T23:53:20.755582+00:00/task_id=extract_currency_conversion_rates permission to 509: [Errno 1] Operation not permitted: '/opt/***/logs/dag_id=col_api_etl/run_id=manual__2023-11-01T23:53:20.755582+00:00/task_id=extract_currency_conversion_rates'
[2023-11-01T23:53:25.210+0000] {taskinstance.py:1159} INFO - Dependencies all met for dep_context=non-requeueable deps ti=<TaskInstance: col_api_etl.extract_currency_conversion_rates manual__2023-11-01T23:53:20.755582+00:00 [queued]>
[2023-11-01T23:53:25.220+0000] {taskinstance.py:1159} INFO - Dependencies all met for dep_context=requeueable deps ti=<TaskInstance: col_api_etl.extract_currency_conversion_rates manual__2023-11-01T23:53:20.755582+00:00 [queued]>
[2023-11-01T23:53:25.221+0000] {taskinstance.py:1361} INFO - Starting attempt 1 of 1
[2023-11-01T23:53:25.237+0000] {taskinstance.py:1382} INFO - Executing <Task(PythonOperator): extract_currency_conversion_rates> on 2023-11-01 23:53:20.755582+00:00
[2023-11-01T23:53:25.243+0000] {standard_task_runner.py:57} INFO - Started process 14940 to run task
[2023-11-01T23:53:25.243+0000] {clientserver.py:543} INFO - Closing down clientserver connection
[2023-11-01T23:53:25.249+0000] {standard_task_runner.py:84} INFO - Running: ['***', 'tasks', 'run', 'col_api_etl', 'extract_currency_conversion_rates', 'manual__2023-11-01T23:53:20.755582+00:00', '--job-id', '1161', '--raw', '--subdir', 'DAGS_FOLDER/col_api_etl.py', '--cfg-path', '/tmp/tmpn8a0y6x1']
[2023-11-01T23:53:25.252+0000] {standard_task_runner.py:85} INFO - Job 1161: Subtask extract_currency_conversion_rates
[2023-11-01T23:53:25.305+0000] {logging_mixin.py:151} INFO - Changing /opt/***/logs/dag_id=col_api_etl/run_id=manual__2023-11-01T23:53:20.755582+00:00/task_id=extract_currency_conversion_rates permission to 509
[2023-11-01T23:53:25.306+0000] {logging_mixin.py:151} INFO - Failed to change /opt/***/logs/dag_id=col_api_etl/run_id=manual__2023-11-01T23:53:20.755582+00:00/task_id=extract_currency_conversion_rates permission to 509: [Errno 1] Operation not permitted: '/opt/***/logs/dag_id=col_api_etl/run_id=manual__2023-11-01T23:53:20.755582+00:00/task_id=extract_currency_conversion_rates'
[2023-11-01T23:53:25.309+0000] {task_command.py:415} INFO - Running <TaskInstance: col_api_etl.extract_currency_conversion_rates manual__2023-11-01T23:53:20.755582+00:00 [running]> on host 65ec58942685
[2023-11-01T23:53:25.395+0000] {taskinstance.py:1660} INFO - Exporting env vars: AIRFLOW_CTX_DAG_OWNER='***' AIRFLOW_CTX_DAG_ID='col_api_etl' AIRFLOW_CTX_TASK_ID='extract_currency_conversion_rates' AIRFLOW_CTX_EXECUTION_DATE='2023-11-01T23:53:20.755582+00:00' AIRFLOW_CTX_TRY_NUMBER='1' AIRFLOW_CTX_DAG_RUN_ID='manual__2023-11-01T23:53:20.755582+00:00'
[2023-11-01T23:53:25.916+0000] {clientserver.py:505} INFO - Error while sending or receiving.
Traceback (most recent call last):
  File "/home/airflow/.local/lib/python3.8/site-packages/py4j/clientserver.py", line 503, in send_command
    self.socket.sendall(command.encode("utf-8"))
ConnectionResetError: [Errno 104] Connection reset by peer
[2023-11-01T23:53:25.918+0000] {clientserver.py:543} INFO - Closing down clientserver connection
[2023-11-01T23:53:25.919+0000] {java_gateway.py:1052} INFO - Exception while sending command.
Traceback (most recent call last):
  File "/home/airflow/.local/lib/python3.8/site-packages/py4j/clientserver.py", line 503, in send_command
    self.socket.sendall(command.encode("utf-8"))
ConnectionResetError: [Errno 104] Connection reset by peer

During handling of the above exception, another exception occurred:

Traceback (most recent call last):
  File "/home/airflow/.local/lib/python3.8/site-packages/py4j/java_gateway.py", line 1038, in send_command
    response = connection.send_command(command)
  File "/home/airflow/.local/lib/python3.8/site-packages/py4j/clientserver.py", line 506, in send_command
    raise Py4JNetworkError(
py4j.protocol.Py4JNetworkError: Error while sending
[2023-11-01T23:53:25.922+0000] {clientserver.py:543} INFO - Closing down clientserver connection
[2023-11-01T23:53:28.886+0000] {python.py:194} INFO - Done. Returned value was: None
[2023-11-01T23:53:28.902+0000] {taskinstance.py:1400} INFO - Marking task as SUCCESS. dag_id=col_api_etl, task_id=extract_currency_conversion_rates, execution_date=20231101T235320, start_date=20231101T235325, end_date=20231101T235328
[2023-11-01T23:53:28.954+0000] {local_task_job_runner.py:228} INFO - Task exited with return code 0
