[2023-10-30T00:16:16.099+0000] {logging_mixin.py:151} INFO - Changing /opt/***/logs/dag_id=col_api_etl/run_id=scheduled__2023-10-29T00:00:00+00:00/task_id=extract_numbeo_prices_from_city permission to 509
[2023-10-30T00:16:16.099+0000] {logging_mixin.py:151} INFO - Failed to change /opt/***/logs/dag_id=col_api_etl/run_id=scheduled__2023-10-29T00:00:00+00:00/task_id=extract_numbeo_prices_from_city permission to 509: [Errno 1] Operation not permitted: '/opt/***/logs/dag_id=col_api_etl/run_id=scheduled__2023-10-29T00:00:00+00:00/task_id=extract_numbeo_prices_from_city'
[2023-10-30T00:16:16.138+0000] {logging_mixin.py:151} INFO - Changing /opt/***/logs/dag_id=col_api_etl/run_id=scheduled__2023-10-29T00:00:00+00:00/task_id=extract_numbeo_prices_from_city permission to 509
[2023-10-30T00:16:16.139+0000] {logging_mixin.py:151} INFO - Failed to change /opt/***/logs/dag_id=col_api_etl/run_id=scheduled__2023-10-29T00:00:00+00:00/task_id=extract_numbeo_prices_from_city permission to 509: [Errno 1] Operation not permitted: '/opt/***/logs/dag_id=col_api_etl/run_id=scheduled__2023-10-29T00:00:00+00:00/task_id=extract_numbeo_prices_from_city'
[2023-10-30T00:16:16.181+0000] {taskinstance.py:1159} INFO - Dependencies all met for dep_context=non-requeueable deps ti=<TaskInstance: col_api_etl.extract_numbeo_prices_from_city scheduled__2023-10-29T00:00:00+00:00 [queued]>
[2023-10-30T00:16:16.191+0000] {taskinstance.py:1159} INFO - Dependencies all met for dep_context=requeueable deps ti=<TaskInstance: col_api_etl.extract_numbeo_prices_from_city scheduled__2023-10-29T00:00:00+00:00 [queued]>
[2023-10-30T00:16:16.192+0000] {taskinstance.py:1361} INFO - Starting attempt 2 of 2
[2023-10-30T00:16:16.207+0000] {taskinstance.py:1382} INFO - Executing <Task(PythonOperator): extract_numbeo_prices_from_city> on 2023-10-29 00:00:00+00:00
[2023-10-30T00:16:16.214+0000] {standard_task_runner.py:57} INFO - Started process 29416 to run task
[2023-10-30T00:16:16.214+0000] {clientserver.py:543} INFO - Closing down clientserver connection
[2023-10-30T00:16:16.220+0000] {standard_task_runner.py:84} INFO - Running: ['***', 'tasks', 'run', 'col_api_etl', 'extract_numbeo_prices_from_city', 'scheduled__2023-10-29T00:00:00+00:00', '--job-id', '1137', '--raw', '--subdir', 'DAGS_FOLDER/col_api_etl.py', '--cfg-path', '/tmp/tmpion1xdcr']
[2023-10-30T00:16:16.222+0000] {standard_task_runner.py:85} INFO - Job 1137: Subtask extract_numbeo_prices_from_city
[2023-10-30T00:16:16.271+0000] {logging_mixin.py:151} INFO - Changing /opt/***/logs/dag_id=col_api_etl/run_id=scheduled__2023-10-29T00:00:00+00:00/task_id=extract_numbeo_prices_from_city permission to 509
[2023-10-30T00:16:16.271+0000] {logging_mixin.py:151} INFO - Failed to change /opt/***/logs/dag_id=col_api_etl/run_id=scheduled__2023-10-29T00:00:00+00:00/task_id=extract_numbeo_prices_from_city permission to 509: [Errno 1] Operation not permitted: '/opt/***/logs/dag_id=col_api_etl/run_id=scheduled__2023-10-29T00:00:00+00:00/task_id=extract_numbeo_prices_from_city'
[2023-10-30T00:16:16.274+0000] {task_command.py:415} INFO - Running <TaskInstance: col_api_etl.extract_numbeo_prices_from_city scheduled__2023-10-29T00:00:00+00:00 [running]> on host ea85de3a6109
[2023-10-30T00:16:16.362+0000] {taskinstance.py:1660} INFO - Exporting env vars: AIRFLOW_CTX_DAG_OWNER='***' AIRFLOW_CTX_DAG_ID='col_api_etl' AIRFLOW_CTX_TASK_ID='extract_numbeo_prices_from_city' AIRFLOW_CTX_EXECUTION_DATE='2023-10-29T00:00:00+00:00' AIRFLOW_CTX_TRY_NUMBER='2' AIRFLOW_CTX_DAG_RUN_ID='scheduled__2023-10-29T00:00:00+00:00'
[2023-10-30T00:16:16.668+0000] {clientserver.py:505} INFO - Error while sending or receiving.
Traceback (most recent call last):
  File "/home/airflow/.local/lib/python3.8/site-packages/py4j/clientserver.py", line 503, in send_command
    self.socket.sendall(command.encode("utf-8"))
ConnectionResetError: [Errno 104] Connection reset by peer
[2023-10-30T00:16:16.670+0000] {clientserver.py:543} INFO - Closing down clientserver connection
[2023-10-30T00:16:16.671+0000] {java_gateway.py:1052} INFO - Exception while sending command.
Traceback (most recent call last):
  File "/home/airflow/.local/lib/python3.8/site-packages/py4j/clientserver.py", line 503, in send_command
    self.socket.sendall(command.encode("utf-8"))
ConnectionResetError: [Errno 104] Connection reset by peer

During handling of the above exception, another exception occurred:

Traceback (most recent call last):
  File "/home/airflow/.local/lib/python3.8/site-packages/py4j/java_gateway.py", line 1038, in send_command
    response = connection.send_command(command)
  File "/home/airflow/.local/lib/python3.8/site-packages/py4j/clientserver.py", line 506, in send_command
    raise Py4JNetworkError(
py4j.protocol.Py4JNetworkError: Error while sending
[2023-10-30T00:16:16.675+0000] {clientserver.py:543} INFO - Closing down clientserver connection
[2023-10-30T00:16:18.045+0000] {logging_mixin.py:151} INFO - Dubai
[2023-10-30T00:16:23.998+0000] {logging_mixin.py:151} INFO - Abu-Dhabi
[2023-10-30T00:16:29.582+0000] {logging_mixin.py:151} INFO - Sharjah
[2023-10-30T00:16:35.202+0000] {logging_mixin.py:151} INFO - Perth
[2023-10-30T00:16:40.777+0000] {logging_mixin.py:151} INFO - Melbourne
[2023-10-30T00:16:46.437+0000] {logging_mixin.py:151} INFO - Sydney
[2023-10-30T00:16:52.251+0000] {logging_mixin.py:151} INFO - Brisbane
[2023-10-30T00:16:57.883+0000] {logging_mixin.py:151} INFO - Hobart
[2023-10-30T00:17:03.229+0000] {logging_mixin.py:151} INFO - Adelaide
[2023-10-30T00:17:09.012+0000] {logging_mixin.py:151} INFO - Canberra
[2023-10-30T00:17:14.687+0000] {logging_mixin.py:151} INFO - Darwin
[2023-10-30T00:17:19.977+0000] {logging_mixin.py:151} INFO - Sarajevo
[2023-10-30T00:17:25.851+0000] {logging_mixin.py:151} INFO - Manama
[2023-10-30T00:17:31.527+0000] {logging_mixin.py:151} INFO - Sofia
[2023-10-30T00:17:37.406+0000] {logging_mixin.py:151} INFO - Sao-Paulo
[2023-10-30T00:17:43.169+0000] {logging_mixin.py:151} INFO - Rio-De-Janeiro
[2023-10-30T00:17:48.758+0000] {logging_mixin.py:151} INFO - Brasilia
[2023-10-30T00:17:54.091+0000] {logging_mixin.py:151} INFO - Toronto
[2023-10-30T00:18:00.027+0000] {logging_mixin.py:151} INFO - Montreal
[2023-10-30T00:18:06.070+0000] {logging_mixin.py:151} INFO - Vancouver
[2023-10-30T00:18:11.624+0000] {logging_mixin.py:151} INFO - Ottawa
[2023-10-30T00:18:17.388+0000] {logging_mixin.py:151} INFO - Calgary
[2023-10-30T00:18:23.013+0000] {logging_mixin.py:151} INFO - Edmonton
[2023-10-30T00:18:28.798+0000] {logging_mixin.py:151} INFO - Halifax
[2023-10-30T00:18:34.314+0000] {logging_mixin.py:151} INFO - Quebec-City
[2023-10-30T00:18:39.879+0000] {logging_mixin.py:151} INFO - Zurich
[2023-10-30T00:18:45.531+0000] {logging_mixin.py:151} INFO - Geneva
[2023-10-30T00:18:50.869+0000] {logging_mixin.py:151} INFO - Zug
[2023-10-30T00:18:56.186+0000] {logging_mixin.py:151} INFO - Basel
[2023-10-30T00:19:01.731+0000] {logging_mixin.py:151} INFO - Bern
[2023-10-30T00:19:07.342+0000] {logging_mixin.py:151} INFO - Lausanne
[2023-10-30T00:19:14.084+0000] {logging_mixin.py:151} INFO - Lugano
[2023-10-30T00:19:21.280+0000] {logging_mixin.py:151} INFO - Vaduz
[2023-10-30T00:19:26.583+0000] {logging_mixin.py:151} INFO - Santiago
[2023-10-30T00:19:32.284+0000] {logging_mixin.py:151} INFO - Chongqing
[2023-10-30T00:19:37.642+0000] {logging_mixin.py:151} INFO - Shanghai
[2023-10-30T00:19:43.234+0000] {logging_mixin.py:151} INFO - Beijing
[2023-10-30T00:19:49.075+0000] {logging_mixin.py:151} INFO - Chengdu
[2023-10-30T00:19:54.334+0000] {logging_mixin.py:151} INFO - Guangzhou
[2023-10-30T00:19:59.649+0000] {logging_mixin.py:151} INFO - Shenzhen
[2023-10-30T00:20:05.373+0000] {logging_mixin.py:151} INFO - Bogota
[2023-10-30T00:20:11.099+0000] {logging_mixin.py:151} INFO - Medellin
[2023-10-30T00:20:16.709+0000] {logging_mixin.py:151} INFO - Cali
[2023-10-30T00:20:22.370+0000] {logging_mixin.py:151} INFO - Cartagena
[2023-10-30T00:20:28.166+0000] {logging_mixin.py:151} INFO - San-Jose
[2023-10-30T00:20:33.888+0000] {logging_mixin.py:151} INFO - Prague
[2023-10-30T00:20:39.881+0000] {logging_mixin.py:151} INFO - Brno
[2023-10-30T00:20:45.508+0000] {logging_mixin.py:151} INFO - Ostrava
[2023-10-30T00:20:51.335+0000] {logging_mixin.py:151} INFO - Copenhagen
[2023-10-30T00:20:57.012+0000] {logging_mixin.py:151} INFO - Aarhus
[2023-10-30T00:21:02.759+0000] {logging_mixin.py:151} INFO - Aalborg
[2023-10-30T00:21:08.062+0000] {logging_mixin.py:151} INFO - Andorra-La-Vella
[2023-10-30T00:21:13.359+0000] {logging_mixin.py:151} INFO - Vienna
[2023-10-30T00:21:19.071+0000] {logging_mixin.py:151} INFO - Salzburg
[2023-10-30T00:21:24.565+0000] {logging_mixin.py:151} INFO - Graz
[2023-10-30T00:21:29.824+0000] {logging_mixin.py:151} INFO - Linz
[2023-10-30T00:21:35.119+0000] {logging_mixin.py:151} INFO - Innsbruck
[2023-10-30T00:21:40.664+0000] {logging_mixin.py:151} INFO - Brussels
[2023-10-30T00:21:46.313+0000] {logging_mixin.py:151} INFO - Antwerp
[2023-10-30T00:21:51.985+0000] {logging_mixin.py:151} INFO - Gent
[2023-10-30T00:21:57.733+0000] {logging_mixin.py:151} INFO - Liege
[2023-10-30T00:22:03.584+0000] {logging_mixin.py:151} INFO - Brugge
[2023-10-30T00:22:09.125+0000] {logging_mixin.py:151} INFO - Zagreb
[2023-10-30T00:22:14.881+0000] {logging_mixin.py:151} INFO - Split
[2023-10-30T00:22:20.485+0000] {logging_mixin.py:151} INFO - Dubrovnik
[2023-10-30T00:22:26.132+0000] {logging_mixin.py:151} INFO - Nicosia
[2023-10-30T00:22:31.450+0000] {logging_mixin.py:151} INFO - Tallinn
[2023-10-30T00:22:37.010+0000] {logging_mixin.py:151} INFO - Tartu
[2023-10-30T00:22:42.548+0000] {logging_mixin.py:151} INFO - Helsinki
[2023-10-30T00:22:47.984+0000] {logging_mixin.py:151} INFO - Turku
[2023-10-30T00:22:53.284+0000] {logging_mixin.py:151} INFO - Tampere
[2023-10-30T00:22:59.168+0000] {logging_mixin.py:151} INFO - Oulu
[2023-10-30T00:23:04.746+0000] {logging_mixin.py:151} INFO - Paris
[2023-10-30T00:23:10.365+0000] {logging_mixin.py:151} INFO - Marseille
[2023-10-30T00:23:15.649+0000] {logging_mixin.py:151} INFO - Lyon
[2023-10-30T00:23:21.010+0000] {logging_mixin.py:151} INFO - Toulouse
[2023-10-30T00:23:26.254+0000] {logging_mixin.py:151} INFO - Nice
[2023-10-30T00:23:31.846+0000] {logging_mixin.py:151} INFO - Nantes
[2023-10-30T00:23:37.345+0000] {logging_mixin.py:151} INFO - Montpellier
[2023-10-30T00:23:42.868+0000] {logging_mixin.py:151} INFO - Berlin
[2023-10-30T00:23:48.727+0000] {logging_mixin.py:151} INFO - Hamburg
[2023-10-30T00:23:54.289+0000] {logging_mixin.py:151} INFO - Munich
[2023-10-30T00:23:59.901+0000] {logging_mixin.py:151} INFO - Stuttgart
[2023-10-30T00:24:05.524+0000] {logging_mixin.py:151} INFO - Frankfurt
[2023-10-30T00:24:11.049+0000] {logging_mixin.py:151} INFO - Cologne
[2023-10-30T00:24:16.657+0000] {logging_mixin.py:151} INFO - Dusseldorf
[2023-10-30T00:24:21.972+0000] {logging_mixin.py:151} INFO - Hanover
[2023-10-30T00:24:27.525+0000] {logging_mixin.py:151} INFO - Dresden
[2023-10-30T00:24:33.163+0000] {logging_mixin.py:151} INFO - Leipzig
[2023-10-30T00:24:38.544+0000] {logging_mixin.py:151} INFO - Athens
[2023-10-30T00:24:44.138+0000] {logging_mixin.py:151} INFO - Crete
[2023-10-30T00:24:49.395+0000] {logging_mixin.py:151} INFO - Thessaloniki
[2023-10-30T00:24:55.043+0000] {logging_mixin.py:151} INFO - Dublin
[2023-10-30T00:25:00.944+0000] {logging_mixin.py:151} INFO - Cork
[2023-10-30T00:25:06.272+0000] {logging_mixin.py:151} INFO - Galway
[2023-10-30T00:25:12.044+0000] {logging_mixin.py:151} INFO - Limerick
[2023-10-30T00:25:17.287+0000] {logging_mixin.py:151} INFO - Rome
[2023-10-30T00:25:22.943+0000] {logging_mixin.py:151} INFO - Milan
[2023-10-30T00:25:28.547+0000] {logging_mixin.py:151} INFO - Naples
[2023-10-30T00:25:38.561+0000] {taskinstance.py:1943} ERROR - Task failed with exception
Traceback (most recent call last):
  File "/home/airflow/.local/lib/python3.8/site-packages/urllib3/connection.py", line 174, in _new_conn
    conn = connection.create_connection(
  File "/home/airflow/.local/lib/python3.8/site-packages/urllib3/util/connection.py", line 72, in create_connection
    for res in socket.getaddrinfo(host, port, family, socket.SOCK_STREAM):
  File "/usr/local/lib/python3.8/socket.py", line 918, in getaddrinfo
    for res in _socket.getaddrinfo(host, port, family, type, proto, flags):
socket.gaierror: [Errno -3] Temporary failure in name resolution

During handling of the above exception, another exception occurred:

Traceback (most recent call last):
  File "/home/airflow/.local/lib/python3.8/site-packages/urllib3/connectionpool.py", line 714, in urlopen
    httplib_response = self._make_request(
  File "/home/airflow/.local/lib/python3.8/site-packages/urllib3/connectionpool.py", line 403, in _make_request
    self._validate_conn(conn)
  File "/home/airflow/.local/lib/python3.8/site-packages/urllib3/connectionpool.py", line 1053, in _validate_conn
    conn.connect()
  File "/home/airflow/.local/lib/python3.8/site-packages/urllib3/connection.py", line 363, in connect
    self.sock = conn = self._new_conn()
  File "/home/airflow/.local/lib/python3.8/site-packages/urllib3/connection.py", line 186, in _new_conn
    raise NewConnectionError(
urllib3.exceptions.NewConnectionError: <urllib3.connection.HTTPSConnection object at 0x7fcb501dea00>: Failed to establish a new connection: [Errno -3] Temporary failure in name resolution

During handling of the above exception, another exception occurred:

Traceback (most recent call last):
  File "/home/airflow/.local/lib/python3.8/site-packages/requests/adapters.py", line 486, in send
    resp = conn.urlopen(
  File "/home/airflow/.local/lib/python3.8/site-packages/urllib3/connectionpool.py", line 798, in urlopen
    retries = retries.increment(
  File "/home/airflow/.local/lib/python3.8/site-packages/urllib3/util/retry.py", line 592, in increment
    raise MaxRetryError(_pool, url, error or ResponseError(cause))
urllib3.exceptions.MaxRetryError: HTTPSConnectionPool(host='www.numbeo.com', port=443): Max retries exceeded with url: /cost-of-living/in/Naples?displayCurrency=USD (Caused by NewConnectionError('<urllib3.connection.HTTPSConnection object at 0x7fcb501dea00>: Failed to establish a new connection: [Errno -3] Temporary failure in name resolution'))

During handling of the above exception, another exception occurred:

Traceback (most recent call last):
  File "/home/airflow/.local/lib/python3.8/site-packages/airflow/operators/python.py", line 192, in execute
    return_value = self.execute_callable()
  File "/home/airflow/.local/lib/python3.8/site-packages/airflow/operators/python.py", line 209, in execute_callable
    return self.python_callable(*self.op_args, **self.op_kwargs)
  File "/opt/airflow/dags/scripts/extraction.py", line 154, in extract_numbeo_prices_from_city
    response = requests.get(f'https://www.numbeo.com/cost-of-living/in/{formatted_city_name}?displayCurrency=USD')
  File "/home/airflow/.local/lib/python3.8/site-packages/requests/api.py", line 73, in get
    return request("get", url, params=params, **kwargs)
  File "/home/airflow/.local/lib/python3.8/site-packages/requests/api.py", line 59, in request
    return session.request(method=method, url=url, **kwargs)
  File "/home/airflow/.local/lib/python3.8/site-packages/requests/sessions.py", line 589, in request
    resp = self.send(prep, **send_kwargs)
  File "/home/airflow/.local/lib/python3.8/site-packages/requests/sessions.py", line 703, in send
    r = adapter.send(request, **kwargs)
  File "/home/airflow/.local/lib/python3.8/site-packages/requests/adapters.py", line 519, in send
    raise ConnectionError(e, request=request)
requests.exceptions.ConnectionError: HTTPSConnectionPool(host='www.numbeo.com', port=443): Max retries exceeded with url: /cost-of-living/in/Naples?displayCurrency=USD (Caused by NewConnectionError('<urllib3.connection.HTTPSConnection object at 0x7fcb501dea00>: Failed to establish a new connection: [Errno -3] Temporary failure in name resolution'))
[2023-10-30T00:25:38.592+0000] {taskinstance.py:1400} INFO - Marking task as FAILED. dag_id=col_api_etl, task_id=extract_numbeo_prices_from_city, execution_date=20231029T000000, start_date=20231030T001616, end_date=20231030T002538
[2023-10-30T00:25:38.613+0000] {standard_task_runner.py:104} ERROR - Failed to execute job 1137 for task extract_numbeo_prices_from_city (HTTPSConnectionPool(host='www.numbeo.com', port=443): Max retries exceeded with url: /cost-of-living/in/Naples?displayCurrency=USD (Caused by NewConnectionError('<urllib3.connection.HTTPSConnection object at 0x7fcb501dea00>: Failed to establish a new connection: [Errno -3] Temporary failure in name resolution')); 29416)
[2023-10-30T00:25:38.648+0000] {local_task_job_runner.py:228} INFO - Task exited with return code 1
