[2023-10-29T01:49:09.385+0000] {logging_mixin.py:151} INFO - Changing /opt/***/logs/dag_id=col_api_etl/run_id=manual__2023-10-29T01:48:56.632395+00:00/task_id=extract_numbeo_prices_from_city permission to 509
[2023-10-29T01:49:09.386+0000] {logging_mixin.py:151} INFO - Failed to change /opt/***/logs/dag_id=col_api_etl/run_id=manual__2023-10-29T01:48:56.632395+00:00/task_id=extract_numbeo_prices_from_city permission to 509: [Errno 1] Operation not permitted: '/opt/***/logs/dag_id=col_api_etl/run_id=manual__2023-10-29T01:48:56.632395+00:00/task_id=extract_numbeo_prices_from_city'
[2023-10-29T01:49:09.411+0000] {logging_mixin.py:151} INFO - Changing /opt/***/logs/dag_id=col_api_etl/run_id=manual__2023-10-29T01:48:56.632395+00:00/task_id=extract_numbeo_prices_from_city permission to 509
[2023-10-29T01:49:09.412+0000] {logging_mixin.py:151} INFO - Failed to change /opt/***/logs/dag_id=col_api_etl/run_id=manual__2023-10-29T01:48:56.632395+00:00/task_id=extract_numbeo_prices_from_city permission to 509: [Errno 1] Operation not permitted: '/opt/***/logs/dag_id=col_api_etl/run_id=manual__2023-10-29T01:48:56.632395+00:00/task_id=extract_numbeo_prices_from_city'
[2023-10-29T01:49:09.443+0000] {taskinstance.py:1159} INFO - Dependencies all met for dep_context=non-requeueable deps ti=<TaskInstance: col_api_etl.extract_numbeo_prices_from_city manual__2023-10-29T01:48:56.632395+00:00 [queued]>
[2023-10-29T01:49:09.452+0000] {taskinstance.py:1159} INFO - Dependencies all met for dep_context=requeueable deps ti=<TaskInstance: col_api_etl.extract_numbeo_prices_from_city manual__2023-10-29T01:48:56.632395+00:00 [queued]>
[2023-10-29T01:49:09.453+0000] {taskinstance.py:1361} INFO - Starting attempt 1 of 2
[2023-10-29T01:49:09.465+0000] {taskinstance.py:1382} INFO - Executing <Task(PythonOperator): extract_numbeo_prices_from_city> on 2023-10-29 01:48:56.632395+00:00
[2023-10-29T01:49:09.469+0000] {standard_task_runner.py:57} INFO - Started process 17302 to run task
[2023-10-29T01:49:09.469+0000] {clientserver.py:543} INFO - Closing down clientserver connection
[2023-10-29T01:49:09.473+0000] {standard_task_runner.py:84} INFO - Running: ['***', 'tasks', 'run', 'col_api_etl', 'extract_numbeo_prices_from_city', 'manual__2023-10-29T01:48:56.632395+00:00', '--job-id', '1095', '--raw', '--subdir', 'DAGS_FOLDER/col_api_etl.py', '--cfg-path', '/tmp/tmpjl4l3nu1']
[2023-10-29T01:49:09.475+0000] {standard_task_runner.py:85} INFO - Job 1095: Subtask extract_numbeo_prices_from_city
[2023-10-29T01:49:09.511+0000] {logging_mixin.py:151} INFO - Changing /opt/***/logs/dag_id=col_api_etl/run_id=manual__2023-10-29T01:48:56.632395+00:00/task_id=extract_numbeo_prices_from_city permission to 509
[2023-10-29T01:49:09.512+0000] {logging_mixin.py:151} INFO - Failed to change /opt/***/logs/dag_id=col_api_etl/run_id=manual__2023-10-29T01:48:56.632395+00:00/task_id=extract_numbeo_prices_from_city permission to 509: [Errno 1] Operation not permitted: '/opt/***/logs/dag_id=col_api_etl/run_id=manual__2023-10-29T01:48:56.632395+00:00/task_id=extract_numbeo_prices_from_city'
[2023-10-29T01:49:09.514+0000] {task_command.py:415} INFO - Running <TaskInstance: col_api_etl.extract_numbeo_prices_from_city manual__2023-10-29T01:48:56.632395+00:00 [running]> on host ea85de3a6109
[2023-10-29T01:49:09.583+0000] {taskinstance.py:1660} INFO - Exporting env vars: AIRFLOW_CTX_DAG_OWNER='***' AIRFLOW_CTX_DAG_ID='col_api_etl' AIRFLOW_CTX_TASK_ID='extract_numbeo_prices_from_city' AIRFLOW_CTX_EXECUTION_DATE='2023-10-29T01:48:56.632395+00:00' AIRFLOW_CTX_TRY_NUMBER='1' AIRFLOW_CTX_DAG_RUN_ID='manual__2023-10-29T01:48:56.632395+00:00'
[2023-10-29T01:49:10.000+0000] {clientserver.py:505} INFO - Error while sending or receiving.
Traceback (most recent call last):
  File "/home/airflow/.local/lib/python3.8/site-packages/py4j/clientserver.py", line 503, in send_command
    self.socket.sendall(command.encode("utf-8"))
ConnectionResetError: [Errno 104] Connection reset by peer
[2023-10-29T01:49:10.012+0000] {clientserver.py:543} INFO - Closing down clientserver connection
[2023-10-29T01:49:10.012+0000] {java_gateway.py:1052} INFO - Exception while sending command.
Traceback (most recent call last):
  File "/home/airflow/.local/lib/python3.8/site-packages/py4j/clientserver.py", line 503, in send_command
    self.socket.sendall(command.encode("utf-8"))
ConnectionResetError: [Errno 104] Connection reset by peer

During handling of the above exception, another exception occurred:

Traceback (most recent call last):
  File "/home/airflow/.local/lib/python3.8/site-packages/py4j/java_gateway.py", line 1038, in send_command
    response = connection.send_command(command)
  File "/home/airflow/.local/lib/python3.8/site-packages/py4j/clientserver.py", line 506, in send_command
    raise Py4JNetworkError(
py4j.protocol.Py4JNetworkError: Error while sending
[2023-10-29T01:49:10.016+0000] {clientserver.py:543} INFO - Closing down clientserver connection
[2023-10-29T01:49:11.088+0000] {logging_mixin.py:151} INFO - Dubai
[2023-10-29T01:49:16.696+0000] {logging_mixin.py:151} INFO - Abu-Dhabi
[2023-10-29T01:49:22.319+0000] {logging_mixin.py:151} INFO - Sharjah
[2023-10-29T01:49:27.950+0000] {logging_mixin.py:151} INFO - Perth
[2023-10-29T01:49:33.632+0000] {logging_mixin.py:151} INFO - Melbourne
[2023-10-29T01:49:39.366+0000] {logging_mixin.py:151} INFO - Sydney
[2023-10-29T01:49:45.125+0000] {logging_mixin.py:151} INFO - Brisbane
[2023-10-29T01:49:50.674+0000] {logging_mixin.py:151} INFO - Hobart
[2023-10-29T01:49:55.939+0000] {logging_mixin.py:151} INFO - Adelaide
[2023-10-29T01:50:01.451+0000] {logging_mixin.py:151} INFO - Canberra
[2023-10-29T01:50:06.783+0000] {logging_mixin.py:151} INFO - Darwin
[2023-10-29T01:50:12.038+0000] {logging_mixin.py:151} INFO - Sarajevo
[2023-10-29T01:50:17.542+0000] {logging_mixin.py:151} INFO - Manama
[2023-10-29T01:50:23.040+0000] {logging_mixin.py:151} INFO - Sofia
[2023-10-29T01:50:28.932+0000] {logging_mixin.py:151} INFO - Sao-Paulo
[2023-10-29T01:50:34.603+0000] {logging_mixin.py:151} INFO - Rio-De-Janeiro
[2023-10-29T01:50:40.213+0000] {logging_mixin.py:151} INFO - Brasilia
[2023-10-29T01:50:45.464+0000] {logging_mixin.py:151} INFO - Toronto
[2023-10-29T01:50:51.450+0000] {logging_mixin.py:151} INFO - Montreal
[2023-10-29T01:50:57.329+0000] {logging_mixin.py:151} INFO - Vancouver
[2023-10-29T01:51:02.999+0000] {logging_mixin.py:151} INFO - Ottawa
[2023-10-29T01:51:08.624+0000] {logging_mixin.py:151} INFO - Calgary
[2023-10-29T01:51:14.190+0000] {logging_mixin.py:151} INFO - Edmonton
[2023-10-29T01:51:19.912+0000] {logging_mixin.py:151} INFO - Halifax
[2023-10-29T01:51:25.519+0000] {logging_mixin.py:151} INFO - Quebec-City
[2023-10-29T01:51:31.031+0000] {logging_mixin.py:151} INFO - Zurich
[2023-10-29T01:51:36.720+0000] {logging_mixin.py:151} INFO - Geneva
[2023-10-29T01:51:42.041+0000] {logging_mixin.py:151} INFO - Zug
[2023-10-29T01:51:47.274+0000] {logging_mixin.py:151} INFO - Basel
[2023-10-29T01:51:52.810+0000] {logging_mixin.py:151} INFO - Bern
[2023-10-29T01:51:58.077+0000] {logging_mixin.py:151} INFO - Lausanne
[2023-10-29T01:52:03.302+0000] {logging_mixin.py:151} INFO - Ticino
[2023-10-29T01:52:08.514+0000] {taskinstance.py:1943} ERROR - Task failed with exception
Traceback (most recent call last):
  File "/home/airflow/.local/lib/python3.8/site-packages/airflow/operators/python.py", line 192, in execute
    return_value = self.execute_callable()
  File "/home/airflow/.local/lib/python3.8/site-packages/airflow/operators/python.py", line 209, in execute_callable
    return self.python_callable(*self.op_args, **self.op_kwargs)
  File "/opt/airflow/dags/scripts/extraction.py", line 137, in extract_numbeo_prices_from_city
    prices_table = numbeo_prices_city_html.find('table', {'class': 'data_wide_table new_bar_table'}).find_all('tr')
AttributeError: 'NoneType' object has no attribute 'find_all'
[2023-10-29T01:52:08.606+0000] {taskinstance.py:1400} INFO - Marking task as UP_FOR_RETRY. dag_id=col_api_etl, task_id=extract_numbeo_prices_from_city, execution_date=20231029T014856, start_date=20231029T014909, end_date=20231029T015208
[2023-10-29T01:52:08.626+0000] {standard_task_runner.py:104} ERROR - Failed to execute job 1095 for task extract_numbeo_prices_from_city ('NoneType' object has no attribute 'find_all'; 17302)
[2023-10-29T01:52:08.660+0000] {local_task_job_runner.py:228} INFO - Task exited with return code 1
